File: Lab2/data/M02C1045CR_1.csv
System ID,,"4483C11306J"
Method name only,,"Tension_Round_NEW"
Test type,,"Tension"
Sample file name,,"M02C1045CR"
Last test date,,"Monday, September 16, 2024"
Last test time,,"4:53:52 PM"
Course,,"NPRE432"
Lab Section Number,,"2"
Group,,"C"
Material,,"1045CR"
Heat Treatment,,"CR"
Other Information,,""
Crosshead Speed,(mm/min),"4.00"
Geometry,,"Circular"
Gage Diameter,(mm),"7.24"
Grip Diameter,(mm),"11.57"
Rockwell Hardness,,"96.1"
Rockwell Scale,,"HRC"
Extensometer Gage Length,(mm),"25.40"
Final Gage Diameter,(mm),"5.53"
Fracture Notes and Location,,"ductile. not much"
Notes During Test,,""

Results Table 1
,,"1"
Maximum Force,(kN),"32.40"
Maximum Strain,(%),"15.67"

Time,Displacement,Force,Strain 1
(s),(mm),(kN),(mm/mm)
"0.00","0.00","0.03124","0.000003093"
"0.50","0.03","0.6532","0.00006969"
"1.00","0.07","1.515","0.0001591"
"1.50","0.10","2.196","0.0002302"
"2.00","0.13","2.727","0.0002760"
"2.50","0.17","3.167","0.0003157"
"3.00","0.20","3.539","0.0003443"
"3.50","0.23","3.865","0.0003677"
"4.00","0.27","4.176","0.0003934"
"4.50","0.30","4.477","0.0004256"
"5.00","0.33","4.778","0.0004611"
"5.50","0.37","5.082","0.0004876"
"6.00","0.40","5.386","0.0005152"
"6.50","0.43","5.692","0.0005401"
"7.00","0.47","5.995","0.0005734"
"7.50","0.50","6.298","0.0006071"
"8.00","0.53","6.600","0.0006376"
"8.50","0.57","6.898","0.0006647"
"9.00","0.60","7.180","0.0007013"
"9.50","0.63","7.459","0.0007295"
"10.00","0.67","7.741","0.0007674"
"10.50","0.70","8.024","0.0007948"
"11.00","0.73","8.300","0.0008325"
"11.50","0.77","8.579","0.0008745"
"12.00","0.80","8.855","0.0009142"
"12.50","0.83","9.143","0.0009504"
"13.00","0.87","9.430","0.0009893"
"13.50","0.90","9.726","0.001034"
"14.00","0.93","10.03","0.001068"
"14.50","0.97","10.32","0.001094"
"15.00","1.00","10.62","0.001115"
"15.50","1.03","10.92","0.001145"
"16.00","1.07","11.22","0.001186"
"16.50","1.10","11.53","0.001215"
"17.00","1.13","11.84","0.001247"
"17.50","1.17","12.15","0.001286"
"18.00","1.20","12.46","0.001314"
"18.50","1.23","12.77","0.001348"
"19.00","1.27","13.09","0.001380"
"19.50","1.30","13.41","0.001416"
"20.00","1.33","13.73","0.001457"
"20.50","1.37","14.05","0.001484"
"21.00","1.40","14.37","0.001523"
"21.50","1.43","14.70","0.001558"
"22.00","1.47","15.03","0.001595"
"22.50","1.50","15.35","0.001633"
"23.00","1.53","15.67","0.001679"
"23.50","1.57","16.00","0.001717"
"24.00","1.60","16.32","0.001751"
"24.50","1.63","16.65","0.001803"
"25.00","1.67","16.97","0.001846"
"25.50","1.70","17.30","0.001896"
"26.00","1.73","17.63","0.001948"
"26.50","1.77","17.96","0.002003"
"27.00","1.80","18.29","0.002062"
"27.50","1.83","18.62","0.002122"
"28.00","1.87","18.94","0.002176"
"28.50","1.90","19.27","0.002251"
"29.00","1.93","19.59","0.002330"
"29.50","1.97","19.91","0.002412"
"30.00","2.00","20.23","0.002491"
"30.50","2.03","20.55","0.002586"
"31.00","2.07","20.87","0.002685"
"31.50","2.10","21.17","0.002796"
"32.00","2.13","21.48","0.002927"
"32.50","2.17","21.78","0.003056"
"33.00","2.20","22.08","0.003192"
"33.50","2.23","22.37","0.003348"
"34.00","2.27","22.65","0.003518"
"34.50","2.30","22.93","0.003702"
"35.00","2.33","23.19","0.003898"
"35.50","2.37","23.46","0.004107"
"36.00","2.40","23.71","0.004329"
"36.50","2.43","23.95","0.004573"
"37.00","2.47","24.20","0.004837"
"37.50","2.50","24.43","0.005091"
"38.00","2.53","24.65","0.005369"
"38.50","2.57","24.87","0.005657"
"39.00","2.60","25.08","0.005960"
"39.50","2.63","25.29","0.006273"
"40.00","2.67","25.49","0.006594"
"40.50","2.70","25.69","0.006929"
"41.00","2.73","25.88","0.007265"
"41.50","2.77","26.08","0.007607"
"42.00","2.80","26.26","0.007958"
"42.50","2.83","26.44","0.008321"
"43.00","2.87","26.62","0.008690"
"43.50","2.90","26.79","0.009055"
"44.00","2.93","26.97","0.009441"
"44.50","2.97","27.13","0.009818"
"45.00","3.00","27.30","0.01022"
"45.50","3.03","27.46","0.01061"
"46.00","3.07","27.62","0.01100"
"46.50","3.10","27.77","0.01142"
"47.00","3.13","27.92","0.01181"
"47.50","3.17","28.08","0.01224"
"48.00","3.20","28.23","0.01265"
"48.50","3.23","28.37","0.01307"
"49.00","3.27","28.52","0.01351"
"49.50","3.30","28.66","0.01393"
"50.00","3.33","28.80","0.01437"
"50.50","3.37","28.93","0.01481"
"51.00","3.40","29.06","0.01526"
"51.50","3.43","29.20","0.01571"
"52.00","3.47","29.32","0.01618"
"52.50","3.50","29.45","0.01664"
"53.00","3.53","29.57","0.01710"
"53.50","3.57","29.69","0.01757"
"54.00","3.60","29.81","0.01806"
"54.50","3.63","29.92","0.01855"
"55.00","3.67","30.03","0.01904"
"55.50","3.70","30.14","0.01953"
"56.00","3.73","30.25","0.02004"
"56.50","3.77","30.35","0.02055"
"57.00","3.80","30.45","0.02108"
"57.50","3.83","30.55","0.02160"
"58.00","3.87","30.64","0.02214"
"58.50","3.90","30.73","0.02268"
"59.00","3.93","30.82","0.02323"
"59.50","3.97","30.90","0.02379"
"60.00","4.00","30.99","0.02437"
"60.50","4.03","31.07","0.02494"
"61.00","4.07","31.15","0.02553"
"61.50","4.10","31.22","0.02612"
"62.00","4.13","31.29","0.02673"
"62.50","4.17","31.36","0.02735"
"63.00","4.20","31.43","0.02797"
"63.50","4.23","31.49","0.02860"
"64.00","4.27","31.55","0.02924"
"64.50","4.30","31.61","0.02991"
"65.00","4.33","31.67","0.03058"
"65.50","4.37","31.72","0.03124"
"66.00","4.40","31.77","0.03192"
"66.50","4.43","31.82","0.03262"
"67.00","4.47","31.86","0.03333"
"67.50","4.50","31.91","0.03404"
"68.00","4.53","31.95","0.03476"
"68.50","4.57","31.98","0.03550"
"69.00","4.60","32.02","0.03625"
"69.50","4.63","32.05","0.03701"
"70.00","4.67","32.09","0.03777"
"70.50","4.70","32.12","0.03854"
"71.00","4.73","32.15","0.03932"
"71.50","4.77","32.17","0.04013"
"72.00","4.80","32.20","0.04094"
"72.50","4.83","32.22","0.04176"
"73.00","4.87","32.24","0.04260"
"73.50","4.90","32.26","0.04345"
"74.00","4.93","32.28","0.04431"
"74.50","4.97","32.30","0.04517"
"75.00","5.00","32.31","0.04605"
"75.50","5.03","32.33","0.04693"
"76.00","5.07","32.34","0.04783"
"76.50","5.10","32.35","0.04873"
"77.00","5.13","32.36","0.04966"
"77.50","5.17","32.37","0.05058"
"78.00","5.20","32.38","0.05153"
"78.50","5.23","32.38","0.05249"
"79.00","5.27","32.39","0.05346"
"79.50","5.30","32.39","0.05444"
"80.00","5.33","32.40","0.05544"
"80.50","5.37","32.40","0.05644"
"81.00","5.40","32.40","0.05746"
"81.50","5.43","32.40","0.05850"
"82.00","5.47","32.40","0.05955"
"82.50","5.50","32.39","0.06061"
"83.00","5.53","32.39","0.06168"
"83.50","5.57","32.38","0.06277"
"84.00","5.60","32.37","0.06387"
"84.50","5.63","32.37","0.06498"
"85.00","5.67","32.36","0.06612"
"85.50","5.70","32.35","0.06725"
"86.00","5.73","32.34","0.06841"
"86.50","5.77","32.32","0.06958"
"87.00","5.80","32.31","0.07077"
"87.50","5.83","32.29","0.07196"
"88.00","5.87","32.27","0.07316"
"88.50","5.90","32.25","0.07439"
"89.00","5.93","32.23","0.07562"
"89.50","5.97","32.21","0.07686"
"90.00","6.00","32.19","0.07812"
"90.50","6.03","32.16","0.07939"
"91.00","6.07","32.13","0.08067"
"91.50","6.10","32.10","0.08195"
"92.00","6.13","32.07","0.08323"
"92.50","6.17","32.04","0.08454"
"93.00","6.20","32.00","0.08584"
"93.50","6.23","31.97","0.08715"
"94.00","6.27","31.93","0.08848"
"94.50","6.30","31.89","0.08980"
"95.00","6.33","31.84","0.09115"
"95.50","6.37","31.80","0.09248"
"96.00","6.40","31.76","0.09382"
"96.50","6.43","31.71","0.09518"
"97.00","6.47","31.66","0.09652"
"97.50","6.50","31.61","0.09788"
"98.00","6.53","31.55","0.09923"
"98.50","6.57","31.50","0.1006"
"99.00","6.60","31.44","0.1019"
"99.50","6.63","31.39","0.1033"
"100.00","6.67","31.33","0.1047"
"100.50","6.70","31.27","0.1060"
"101.00","6.73","31.21","0.1074"
"101.50","6.77","31.15","0.1088"
"102.00","6.80","31.08","0.1102"
"102.50","6.83","31.01","0.1115"
"103.00","6.87","30.95","0.1129"
"103.50","6.90","30.88","0.1143"
"104.00","6.93","30.80","0.1157"
"104.50","6.97","30.73","0.1170"
"105.00","7.00","30.66","0.1184"
"105.50","7.03","30.58","0.1198"
"106.00","7.07","30.50","0.1212"
"106.50","7.10","30.42","0.1226"
"107.00","7.13","30.34","0.1240"
"107.50","7.17","30.26","0.1254"
"108.00","7.20","30.17","0.1268"
"108.50","7.23","30.08","0.1282"
"109.00","7.27","29.99","0.1296"
"109.50","7.30","29.90","0.1310"
"110.00","7.33","29.81","0.1324"
"110.50","7.37","29.71","0.1338"
"111.00","7.40","29.62","0.1352"
"111.50","7.43","29.51","0.1366"
"112.00","7.47","29.41","0.1380"
"112.50","7.50","29.31","0.1394"
"113.00","7.53","29.20","0.1409"
"113.50","7.57","29.09","0.1423"
"114.00","7.60","28.98","0.1437"
"114.50","7.63","28.86","0.1451"
"115.00","7.67","28.74","0.1466"
"115.50","7.70","28.62","0.1480"
"116.00","7.73","28.49","0.1494"
"116.50","7.77","28.36","0.1509"
"117.00","7.80","28.22","0.1523"
"117.50","7.83","28.08","0.1537"
"118.00","7.87","27.93","0.1552"
"118.50","7.90","27.75","0.1567"
"118.90","7.93","15.65","0.1487"