File: Lab2/data/N02B7075T6_1.csv
System ID,,"4483C11302J"
Method name only,,"Tension_Round_NEW"
Test type,,"Tension"
Sample file name,,"N02B7075T6"
Last test date,,"Monday, September 16, 2024"
Last test time,,"5:06:07 PM"
Course,,"NPRE 432"
Lab Section Number,,"02"
Group,,"B"
Material,,"7075-T6"
Heat Treatment,,""
Other Information,,""
Crosshead Speed,(mm/min),"4.00"
Geometry,,"Circular"
Gage Diameter,(mm),"7.18"
Grip Diameter,(mm),"12.74"
Rockwell Hardness,,"86.8"
Rockwell Scale,,"HRB"
Extensometer Gage Length,(mm),"25.40"
Final Gage Diameter,(mm),"6.28"
Fracture Notes and Location,,""
Notes During Test,,""

Results Table 1
,,"1"
Maximum Force,(kN),"22.47"
Maximum Strain,(%),"15.78"

Time,Displacement,Force,Strain 1
(s),(mm),(kN),(mm/mm)
"0.00","0.05","-0.03596","0.00005336"
"0.50","0.08","0.3380","0.0001765"
"1.00","0.12","0.7403","0.0003289"
"1.50","0.15","0.9842","0.0004337"
"2.00","0.18","1.221","0.0005352"
"2.50","0.22","1.441","0.0006261"
"3.00","0.25","1.635","0.0006872"
"3.50","0.28","1.810","0.0007612"
"4.00","0.32","1.973","0.0008254"
"4.50","0.35","2.130","0.0008813"
"5.00","0.38","2.286","0.0009416"
"5.50","0.42","2.447","0.001005"
"6.00","0.45","2.612","0.001067"
"6.50","0.48","2.779","0.001127"
"7.00","0.52","2.951","0.001193"
"7.50","0.55","3.122","0.001261"
"8.00","0.58","3.291","0.001319"
"8.50","0.62","3.458","0.001378"
"9.00","0.65","3.617","0.001436"
"9.50","0.68","3.773","0.001497"
"10.00","0.72","3.929","0.001551"
"10.50","0.75","4.083","0.001606"
"11.00","0.78","4.235","0.001660"
"11.50","0.82","4.389","0.001724"
"12.00","0.85","4.544","0.001789"
"12.50","0.88","4.705","0.001851"
"13.00","0.92","4.873","0.001920"
"13.50","0.95","5.043","0.001981"
"14.00","0.98","5.218","0.002052"
"14.50","1.02","5.398","0.002114"
"15.00","1.05","5.578","0.002185"
"15.50","1.08","5.765","0.002255"
"16.00","1.12","5.951","0.002319"
"16.50","1.15","6.142","0.002388"
"17.00","1.18","6.338","0.002467"
"17.50","1.22","6.534","0.002535"
"18.00","1.25","6.733","0.002612"
"18.50","1.28","6.936","0.002682"
"19.00","1.32","7.141","0.002761"
"19.50","1.35","7.347","0.002832"
"20.00","1.38","7.556","0.002913"
"20.50","1.42","7.767","0.002989"
"21.00","1.45","7.979","0.003068"
"21.50","1.48","8.197","0.003144"
"22.00","1.52","8.412","0.003228"
"22.50","1.55","8.630","0.003305"
"23.00","1.58","8.853","0.003391"
"23.50","1.62","9.073","0.003467"
"24.00","1.65","9.299","0.003553"
"24.50","1.68","9.526","0.003635"
"25.00","1.72","9.754","0.003718"
"25.50","1.75","9.986","0.003804"
"26.00","1.78","10.22","0.003892"
"26.50","1.82","10.45","0.003974"
"27.00","1.85","10.69","0.004062"
"27.50","1.88","10.93","0.004155"
"28.00","1.92","11.17","0.004238"
"28.50","1.95","11.42","0.004332"
"29.00","1.98","11.66","0.004423"
"29.50","2.02","11.91","0.004519"
"30.00","2.05","12.15","0.004608"
"30.50","2.08","12.40","0.004699"
"31.00","2.12","12.65","0.004790"
"31.50","2.15","12.91","0.004887"
"32.00","2.18","13.16","0.004983"
"32.50","2.22","13.41","0.005080"
"33.00","2.25","13.67","0.005168"
"33.50","2.28","13.92","0.005266"
"34.00","2.32","14.18","0.005365"
"34.50","2.35","14.43","0.005456"
"35.00","2.38","14.69","0.005550"
"35.50","2.42","14.95","0.005647"
"36.00","2.45","15.20","0.005748"
"36.50","2.48","15.46","0.005845"
"37.00","2.52","15.72","0.005948"
"37.50","2.55","15.99","0.006047"
"38.00","2.58","16.25","0.006153"
"38.50","2.62","16.51","0.006250"
"39.00","2.65","16.77","0.006351"
"39.50","2.68","17.04","0.006455"
"40.00","2.72","17.30","0.006564"
"40.50","2.75","17.56","0.006671"
"41.00","2.78","17.83","0.006778"
"41.50","2.82","18.10","0.006891"
"42.00","2.85","18.36","0.007004"
"42.50","2.88","18.62","0.007124"
"43.00","2.92","18.88","0.007249"
"43.50","2.95","19.13","0.007390"
"44.00","2.98","19.38","0.007556"
"44.50","3.02","19.61","0.007762"
"45.00","3.05","19.81","0.008024"
"45.50","3.08","19.98","0.008373"
"46.00","3.12","20.12","0.008811"
"46.50","3.15","20.24","0.009311"
"47.00","3.18","20.35","0.009867"
"47.50","3.22","20.43","0.01046"
"48.00","3.25","20.51","0.01110"
"48.50","3.28","20.58","0.01177"
"49.00","3.32","20.64","0.01246"
"49.50","3.35","20.70","0.01317"
"50.00","3.38","20.76","0.01391"
"50.50","3.42","20.80","0.01466"
"51.00","3.45","20.85","0.01541"
"51.50","3.48","20.89","0.01618"
"52.00","3.52","20.93","0.01694"
"52.50","3.55","20.97","0.01772"
"53.00","3.58","21.01","0.01850"
"53.50","3.62","21.04","0.01928"
"54.00","3.65","21.08","0.02005"
"54.50","3.68","21.11","0.02083"
"55.00","3.72","21.14","0.02162"
"55.50","3.75","21.18","0.02240"
"56.00","3.78","21.21","0.02319"
"56.50","3.82","21.24","0.02397"
"57.00","3.85","21.27","0.02475"
"57.50","3.88","21.30","0.02554"
"58.00","3.92","21.33","0.02632"
"58.50","3.95","21.36","0.02710"
"59.00","3.98","21.38","0.02789"
"59.50","4.02","21.41","0.02867"
"60.00","4.05","21.44","0.02945"
"60.50","4.08","21.46","0.03024"
"61.00","4.12","21.49","0.03102"
"61.50","4.15","21.51","0.03181"
"62.00","4.18","21.54","0.03259"
"62.50","4.22","21.56","0.03338"
"63.00","4.25","21.59","0.03417"
"63.50","4.28","21.61","0.03495"
"64.00","4.32","21.64","0.03574"
"64.50","4.35","21.66","0.03653"
"65.00","4.38","21.68","0.03732"
"65.50","4.42","21.71","0.03811"
"66.00","4.45","21.73","0.03890"
"66.50","4.48","21.75","0.03969"
"67.00","4.52","21.77","0.04049"
"67.50","4.55","21.79","0.04128"
"68.00","4.58","21.81","0.04207"
"68.50","4.62","21.83","0.04287"
"69.00","4.65","21.85","0.04366"
"69.50","4.68","21.87","0.04446"
"70.00","4.72","21.89","0.04526"
"70.50","4.75","21.91","0.04606"
"71.00","4.78","21.93","0.04687"
"71.50","4.82","21.95","0.04767"
"72.00","4.85","21.97","0.04847"
"72.50","4.88","21.99","0.04929"
"73.00","4.92","22.00","0.05010"
"73.50","4.95","22.02","0.05092"
"74.00","4.98","22.04","0.05172"
"74.50","5.02","22.05","0.05254"
"75.00","5.05","22.07","0.05336"
"75.50","5.08","22.08","0.05417"
"76.00","5.12","22.10","0.05500"
"76.50","5.15","22.11","0.05582"
"77.00","5.18","22.13","0.05665"
"77.50","5.22","22.14","0.05748"
"78.00","5.25","22.16","0.05830"
"78.50","5.28","22.17","0.05913"
"79.00","5.32","22.19","0.05997"
"79.50","5.35","22.20","0.06080"
"80.00","5.38","22.21","0.06164"
"80.50","5.42","22.22","0.06248"
"81.00","5.45","22.24","0.06332"
"81.50","5.48","22.25","0.06416"
"82.00","5.52","22.26","0.06501"
"82.50","5.55","22.27","0.06586"
"83.00","5.58","22.28","0.06671"
"83.50","5.62","22.29","0.06757"
"84.00","5.65","22.31","0.06843"
"84.50","5.68","22.32","0.06929"
"85.00","5.72","22.32","0.07015"
"85.50","5.75","22.34","0.07102"
"86.00","5.78","22.34","0.07189"
"86.50","5.82","22.35","0.07277"
"87.00","5.85","22.36","0.07365"
"87.50","5.88","22.37","0.07452"
"88.00","5.92","22.38","0.07541"
"88.50","5.95","22.39","0.07630"
"89.00","5.98","22.39","0.07720"
"89.50","6.02","22.40","0.07809"
"90.00","6.05","22.41","0.07899"
"90.50","6.08","22.42","0.07990"
"91.00","6.12","22.42","0.08081"
"91.50","6.15","22.43","0.08172"
"92.00","6.18","22.43","0.08263"
"92.50","6.22","22.44","0.08355"
"93.00","6.25","22.45","0.08448"
"93.50","6.28","22.45","0.08541"
"94.00","6.32","22.46","0.08635"
"94.50","6.35","22.46","0.08730"
"95.00","6.38","22.46","0.08825"
"95.50","6.42","22.47","0.08921"
"96.00","6.45","22.47","0.09017"
"96.50","6.48","22.47","0.09115"
"97.00","6.52","22.47","0.09213"
"97.50","6.55","22.47","0.09311"
"98.00","6.58","22.47","0.09410"
"98.50","6.62","22.47","0.09510"
"99.00","6.65","22.47","0.09611"
"99.50","6.68","22.47","0.09713"
"100.00","6.72","22.47","0.09815"
"100.50","6.75","22.46","0.09919"
"101.00","6.78","22.46","0.1002"
"101.50","6.82","22.46","0.1013"
"102.00","6.85","22.45","0.1023"
"102.50","6.88","22.44","0.1034"
"103.00","6.92","22.44","0.1045"
"103.50","6.95","22.43","0.1056"
"104.00","6.98","22.42","0.1067"
"104.50","7.02","22.41","0.1078"
"105.00","7.05","22.40","0.1089"
"105.50","7.08","22.39","0.1101"
"106.00","7.12","22.37","0.1112"
"106.50","7.15","22.35","0.1124"
"107.00","7.18","22.34","0.1136"
"107.50","7.22","22.32","0.1148"
"108.00","7.25","22.30","0.1160"
"108.50","7.28","22.27","0.1172"
"109.00","7.32","22.25","0.1184"
"109.50","7.35","22.22","0.1196"
"110.00","7.38","22.20","0.1209"
"110.50","7.42","22.16","0.1221"
"111.00","7.45","22.13","0.1234"
"111.50","7.48","22.10","0.1246"
"112.00","7.52","22.06","0.1259"
"112.50","7.55","22.02","0.1272"
"113.00","7.58","21.98","0.1285"
"113.50","7.62","21.94","0.1298"
"114.00","7.65","21.89","0.1311"
"114.50","7.68","21.84","0.1324"
"115.00","7.72","21.79","0.1338"
"115.50","7.75","21.74","0.1351"
"116.00","7.78","21.68","0.1364"
"116.50","7.82","21.62","0.1377"
"117.00","7.85","21.55","0.1391"
"117.50","7.88","21.49","0.1405"
"118.00","7.92","21.42","0.1418"
"118.50","7.95","21.35","0.1432"
"119.00","7.98","21.28","0.1446"
"119.50","8.02","21.20","0.1460"
"120.00","8.05","21.12","0.1474"
"120.50","8.08","21.03","0.1488"
"121.00","8.12","20.95","0.1502"
"121.50","8.15","20.85","0.1516"
"122.00","8.18","20.75","0.1530"
"122.50","8.22","20.64","0.1545"
"122.56","8.22","11.87","0.1578"