File: Lab2/data/N02D1018CR_1.csv
System ID,,"4483C1713"
Method name only,,"Tension_Round_NEW"
Test type,,"Tension"
Sample file name,,"N02D1018CR"
Last test date,,"Monday, September 16, 2024"
Last test time,,"4:38:28 PM"
Course,,"NPRE 432"
Lab Section Number,,"02"
Group,,"D"
Material,,"1018"
Heat Treatment,,"CR"
Other Information,,""
Crosshead Speed,(mm/min),"4.00"
Geometry,,"Circular"
Gage Diameter,(mm),"7.25"
Grip Diameter,(mm),"12.74"
Rockwell Hardness,,"94.3"
Rockwell Scale,,"HRB"
Extensometer Gage Length,(mm),"25.40"
Final Gage Diameter,(mm),"4.64"
Fracture Notes and Location,,"DUCTILE FRACTURE, CUP AND CONE SHAPE"
Notes During Test,,""

Results Table 1
,,"1"
Maximum Force,(kN),"27.64"
Maximum Strain,(%),"15.36"

Time,Displacement,Force,Strain 1
(s),(mm),(kN),(mm/mm)
"0.00","0.00","0.4347","-0.000007598"
"0.50","0.03","1.372","0.00003108"
"1.00","0.07","2.256","0.0001743"
"1.50","0.10","2.995","0.0002316"
"2.00","0.13","3.594","0.0003286"
"2.50","0.17","4.103","0.0004106"
"3.00","0.20","4.547","0.0004464"
"3.50","0.23","4.922","0.0005116"
"4.00","0.27","5.278","0.0005491"
"4.50","0.30","5.608","0.0005904"
"5.00","0.33","5.928","0.0006412"
"5.50","0.37","6.239","0.0006630"
"6.00","0.40","6.538","0.0007100"
"6.50","0.43","6.815","0.0007407"
"7.00","0.47","7.091","0.0007685"
"7.50","0.50","7.361","0.0008178"
"8.00","0.53","7.632","0.0008439"
"8.50","0.57","7.907","0.0008579"
"9.00","0.60","8.164","0.0009143"
"9.50","0.63","8.423","0.0009266"
"10.00","0.67","8.675","0.0009728"
"10.50","0.70","8.933","0.0009839"
"11.00","0.73","9.196","0.001031"
"11.50","0.77","9.456","0.001049"
"12.00","0.80","9.715","0.001063"
"12.50","0.83","9.981","0.001096"
"13.00","0.87","10.25","0.001120"
"13.50","0.90","10.53","0.001148"
"14.00","0.93","10.80","0.001176"
"14.50","0.97","11.08","0.001213"
"15.00","1.00","11.36","0.001245"
"15.50","1.03","11.65","0.001320"
"16.00","1.07","11.93","0.001329"
"16.50","1.10","12.21","0.001352"
"17.00","1.13","12.50","0.001380"
"17.50","1.17","12.79","0.001422"
"18.00","1.20","13.09","0.001445"
"18.50","1.23","13.38","0.001482"
"19.00","1.27","13.67","0.001515"
"19.50","1.30","13.97","0.001580"
"20.00","1.33","14.27","0.001598"
"20.50","1.37","14.53","0.001671"
"21.00","1.40","14.85","0.001689"
"21.50","1.43","15.15","0.001700"
"22.00","1.47","15.46","0.001723"
"22.50","1.50","15.77","0.001755"
"23.00","1.53","16.08","0.001799"
"23.50","1.57","16.38","0.001863"
"24.00","1.60","16.69","0.001877"
"24.50","1.63","17.01","0.001906"
"25.00","1.67","17.32","0.001954"
"25.50","1.70","17.64","0.001992"
"26.00","1.73","17.95","0.002020"
"26.50","1.77","18.27","0.002070"
"27.00","1.80","18.60","0.002114"
"27.50","1.83","18.92","0.002147"
"28.00","1.87","19.24","0.002194"
"28.50","1.90","19.57","0.002235"
"29.00","1.93","19.90","0.002272"
"29.50","1.97","20.24","0.002325"
"30.00","2.00","20.56","0.002356"
"30.50","2.03","20.90","0.002399"
"31.00","2.07","21.24","0.002438"
"31.50","2.10","21.57","0.002476"
"32.00","2.13","21.91","0.002527"
"32.50","2.17","22.25","0.002568"
"33.00","2.20","22.58","0.002609"
"33.50","2.23","22.92","0.002665"
"34.00","2.27","23.26","0.002722"
"34.50","2.30","23.59","0.002774"
"35.00","2.33","23.93","0.002827"
"35.50","2.37","24.27","0.002900"
"36.00","2.40","24.59","0.002978"
"36.50","2.43","24.91","0.003069"
"37.00","2.47","25.22","0.003184"
"37.50","2.50","25.52","0.003317"
"38.00","2.53","25.79","0.003496"
"38.50","2.57","26.05","0.003730"
"39.00","2.60","26.26","0.004002"
"39.50","2.63","26.47","0.004351"
"40.00","2.67","26.65","0.004718"
"40.50","2.70","26.81","0.005133"
"41.00","2.73","26.96","0.005601"
"41.50","2.77","27.08","0.006121"
"42.00","2.80","27.18","0.006687"
"42.50","2.83","27.25","0.007323"
"43.00","2.87","27.30","0.008001"
"43.50","2.90","27.34","0.008717"
"44.00","2.93","27.37","0.009466"
"44.50","2.97","27.40","0.01026"
"45.00","3.00","27.42","0.01108"
"45.50","3.03","27.45","0.01189"
"46.00","3.07","27.47","0.01274"
"46.50","3.10","27.49","0.01357"
"47.00","3.13","27.51","0.01442"
"47.50","3.17","27.52","0.01529"
"48.00","3.20","27.54","0.01616"
"48.50","3.23","27.56","0.01704"
"49.00","3.27","27.57","0.01790"
"49.50","3.30","27.58","0.01880"
"50.00","3.33","27.60","0.01968"
"50.50","3.37","27.61","0.02058"
"51.00","3.40","27.62","0.02148"
"51.50","3.43","27.62","0.02239"
"52.00","3.47","27.63","0.02330"
"52.50","3.50","27.64","0.02422"
"53.00","3.53","27.64","0.02515"
"53.50","3.57","27.64","0.02607"
"54.00","3.60","27.64","0.02700"
"54.50","3.63","27.64","0.02796"
"55.00","3.67","27.63","0.02891"
"55.50","3.70","27.63","0.02987"
"56.00","3.73","27.62","0.03085"
"56.50","3.77","27.61","0.03185"
"57.00","3.80","27.59","0.03286"
"57.50","3.83","27.57","0.03389"
"58.00","3.87","27.55","0.03494"
"58.50","3.90","27.52","0.03599"
"59.00","3.93","27.48","0.03706"
"59.50","3.97","27.45","0.03816"
"60.00","4.00","27.40","0.03928"
"60.50","4.03","27.35","0.04040"
"61.00","4.07","27.30","0.04156"
"61.50","4.10","27.24","0.04273"
"62.00","4.13","27.18","0.04391"
"62.50","4.17","27.11","0.04509"
"63.00","4.20","27.05","0.04629"
"63.50","4.23","26.97","0.04750"
"64.00","4.27","26.90","0.04871"
"64.50","4.30","26.83","0.04994"
"65.00","4.33","26.75","0.05117"
"65.50","4.37","26.67","0.05243"
"66.00","4.40","26.59","0.05368"
"66.50","4.43","26.51","0.05494"
"67.00","4.47","26.43","0.05618"
"67.50","4.50","26.35","0.05744"
"68.00","4.53","26.27","0.05871"
"68.50","4.57","26.18","0.05999"
"69.00","4.60","26.10","0.06126"
"69.50","4.63","26.02","0.06255"
"70.00","4.67","25.93","0.06383"
"70.50","4.70","25.85","0.06513"
"71.00","4.73","25.77","0.06643"
"71.50","4.77","25.68","0.06771"
"72.00","4.80","25.59","0.06904"
"72.50","4.83","25.51","0.07034"
"73.00","4.87","25.42","0.07164"
"73.50","4.90","25.34","0.07294"
"74.00","4.93","25.25","0.07426"
"74.50","4.97","25.16","0.07557"
"75.00","5.00","25.07","0.07689"
"75.50","5.03","24.98","0.07820"
"76.00","5.07","24.89","0.07953"
"76.50","5.10","24.81","0.08085"
"77.00","5.13","24.71","0.08218"
"77.50","5.17","24.62","0.08352"
"78.00","5.20","24.53","0.08486"
"78.50","5.23","24.43","0.08620"
"79.00","5.27","24.34","0.08756"
"79.50","5.30","24.25","0.08891"
"80.00","5.33","24.15","0.09026"
"80.50","5.37","24.05","0.09162"
"81.00","5.40","23.95","0.09299"
"81.50","5.43","23.85","0.09435"
"82.00","5.47","23.75","0.09572"
"82.50","5.50","23.65","0.09707"
"83.00","5.53","23.55","0.09845"
"83.50","5.57","23.45","0.09982"
"84.00","5.60","23.34","0.1012"
"84.50","5.63","23.24","0.1026"
"85.00","5.67","23.13","0.1039"
"85.50","5.70","23.02","0.1053"
"86.00","5.73","22.91","0.1067"
"86.50","5.77","22.81","0.1081"
"87.00","5.80","22.70","0.1095"
"87.50","5.83","22.58","0.1108"
"88.00","5.87","22.47","0.1123"
"88.50","5.90","22.35","0.1136"
"89.00","5.93","22.24","0.1150"
"89.50","5.97","22.12","0.1164"
"90.00","6.00","22.00","0.1178"
"90.50","6.03","21.88","0.1192"
"91.00","6.07","21.76","0.1206"
"91.50","6.10","21.64","0.1220"
"92.00","6.13","21.51","0.1235"
"92.50","6.17","21.39","0.1249"
"93.00","6.20","21.26","0.1263"
"93.50","6.23","21.13","0.1277"
"94.00","6.27","21.00","0.1291"
"94.50","6.30","20.86","0.1305"
"95.00","6.33","20.73","0.1319"
"95.50","6.37","20.59","0.1334"
"96.00","6.40","20.45","0.1348"
"96.50","6.43","20.31","0.1362"
"97.00","6.47","20.16","0.1376"
"97.50","6.50","20.01","0.1391"
"98.00","6.53","19.86","0.1405"
"98.50","6.57","19.71","0.1420"
"99.00","6.60","19.55","0.1434"
"99.50","6.63","19.40","0.1448"
"100.00","6.67","19.23","0.1463"
"100.50","6.70","19.07","0.1477"
"101.00","6.73","18.90","0.1492"
"101.50","6.77","18.72","0.1507"
"102.00","6.80","18.54","0.1521"
"102.50","6.83","18.36","0.1536"
"102.89","6.86","10.25","0.1320"