File: Lab2/data/N02DBR_1.csv
System ID,,"4483C1713"
Method name only,,"Tension_Round_Reversals_Brass_NEW"
Test type,,"Tension TestProfiler"
Sample file name,,"N02DBR"
Last test date,,"Monday, September 16, 2024"
Last test time,,"5:52:00 PM"
Course,,"NPRE 432"
Lab Section Number,,"02"
Group,,"D"
Material,,"BR"
Heat Treatment,,""
Other Information,,""
Geometry,,"Circular"
Gage Diameter,(mm),"7.20"
Grip Diameter,(mm),"12.78"
Rockwell Hardness,,"66.4"
Rockwell Scale,,"HRB"
Extensometer Gage Length,(mm),"25.40"
Final Gage Diameter (at Neck),(mm),"4.69"
Uniform Gage Diameter in mm (away from Neck),,"6.74"
Final Hardness at Uniform Gage Diameter,,"69.4"
Rockwell Scale,,"HRB"
Fracture Notes and Location,,""
Notes During Test,,""

Results Table 1
,,"1"
Maximum Force,(kN),"15.89"
Maximum Strain,(%),"29.52"

Time,Displacement,Force,Strain 1
(s),(mm),(kN),(mm/mm)
"0.00","0.00","0.2988","-0.00001178"
"0.50","0.03","0.8753","0.0001994"
"1.00","0.07","1.301","0.0003447"
"1.50","0.10","1.575","0.0004138"
"2.00","0.13","1.808","0.0005068"
"2.50","0.17","2.050","0.0005830"
"3.00","0.20","2.272","0.0006626"
"3.50","0.23","2.472","0.0007475"
"4.00","0.27","2.668","0.0008040"
"4.50","0.30","2.863","0.0008921"
"5.00","0.33","3.062","0.0009582"
"5.50","0.37","3.261","0.001039"
"6.00","0.40","3.465","0.001107"
"6.50","0.43","3.671","0.001197"
"7.00","0.47","3.880","0.001274"
"7.50","0.50","4.093","0.001364"
"8.00","0.53","4.313","0.001444"
"8.50","0.57","4.537","0.001532"
"9.00","0.60","4.762","0.001616"
"9.50","0.63","4.993","0.001705"
"9.51","0.63","5.001","0.001704"
"9.52","0.63","5.002","0.001705"
"9.65","0.64","5.060","0.001724"
"10.15","0.61","4.289","0.001438"
"10.65","0.58","3.516","0.001152"
"11.15","0.54","2.800","0.0008796"
"11.65","0.51","2.131","0.0006279"
"12.15","0.48","1.603","0.0004055"
"12.65","0.44","1.302","0.0003080"
"13.05","0.42","0.9993","0.0001929"
"13.05","0.42","0.9978","0.0001922"
"13.06","0.42","0.9962","0.0001908"
"13.56","0.45","1.649","0.0004343"
"14.06","0.48","2.365","0.0006980"
"14.56","0.52","3.045","0.0009655"
"15.06","0.55","3.637","0.001189"
"15.56","0.58","4.116","0.001365"
"16.06","0.62","4.580","0.001550"
"16.56","0.65","5.009","0.001719"
"17.06","0.68","5.298","0.001817"
"17.56","0.72","5.534","0.001905"
"18.06","0.75","5.761","0.002005"
"18.56","0.78","5.985","0.002088"
"19.06","0.82","6.209","0.002174"
"19.56","0.85","6.432","0.002264"
"20.06","0.88","6.649","0.002361"
"20.56","0.92","6.863","0.002432"
"21.06","0.95","7.076","0.002541"
"21.56","0.98","7.289","0.002638"
"22.06","1.02","7.501","0.002734"
"22.56","1.05","7.704","0.002839"
"23.06","1.08","7.903","0.002935"
"23.56","1.12","8.098","0.003032"
"24.06","1.15","8.288","0.003126"
"24.56","1.18","8.481","0.003234"
"25.06","1.22","8.672","0.003340"
"25.56","1.25","8.864","0.003463"
"26.06","1.28","9.056","0.003574"
"26.56","1.32","9.249","0.003708"
"27.06","1.35","9.442","0.003835"
"27.56","1.38","9.632","0.003971"
"28.06","1.42","9.821","0.004099"
"28.56","1.45","10.01","0.004237"
"29.06","1.48","10.19","0.004391"
"29.56","1.52","10.38","0.004550"
"30.06","1.55","10.56","0.004718"
"30.56","1.58","10.74","0.004902"
"31.06","1.62","10.91","0.005085"
"31.56","1.65","11.08","0.005303"
"32.06","1.68","11.24","0.005549"
"32.56","1.72","11.39","0.005811"
"33.06","1.75","11.54","0.006115"
"33.56","1.78","11.67","0.006478"
"34.06","1.82","11.78","0.006888"
"34.56","1.85","11.88","0.007351"
"35.06","1.88","11.97","0.007858"
"35.56","1.92","12.04","0.008400"
"36.06","1.95","12.11","0.009008"
"36.56","1.98","12.18","0.009621"
"37.06","2.02","12.24","0.01025"
"37.56","2.05","12.30","0.01089"
"38.06","2.08","12.35","0.01155"
"38.56","2.12","12.40","0.01222"
"39.06","2.15","12.45","0.01287"
"39.56","2.18","12.50","0.01353"
"40.06","2.22","12.55","0.01420"
"40.56","2.25","12.60","0.01487"
"41.06","2.28","12.64","0.01556"
"41.56","2.32","12.68","0.01622"
"42.06","2.35","12.73","0.01690"
"42.56","2.38","12.77","0.01758"
"43.06","2.42","12.81","0.01826"
"43.56","2.45","12.85","0.01893"
"44.06","2.48","12.89","0.01961"
"44.34","2.50","12.92","0.02000"
"44.34","2.50","12.92","0.02000"
"44.39","2.50","12.92","0.02008"
"44.89","2.47","12.14","0.01992"
"45.39","2.44","11.39","0.01961"
"45.89","2.40","10.67","0.01933"
"46.39","2.37","9.973","0.01904"
"46.89","2.34","9.278","0.01874"
"47.39","2.30","8.580","0.01845"
"47.89","2.27","7.900","0.01816"
"48.39","2.24","7.221","0.01786"
"48.89","2.20","6.556","0.01756"
"49.39","2.17","5.916","0.01727"
"49.89","2.14","5.315","0.01698"
"50.39","2.10","4.847","0.01675"
"50.89","2.07","4.556","0.01661"
"51.39","2.04","4.306","0.01649"
"51.89","2.00","4.067","0.01636"
"52.39","1.97","3.838","0.01625"
"52.89","1.94","3.608","0.01614"
"53.39","1.90","3.384","0.01603"
"53.89","1.87","3.170","0.01592"
"54.39","1.84","2.960","0.01580"
"54.89","1.80","2.760","0.01570"
"55.39","1.77","2.564","0.01560"
"55.89","1.74","2.371","0.01551"
"56.39","1.70","2.179","0.01539"
"56.89","1.67","1.941","0.01526"
"57.39","1.64","1.700","0.01513"
"57.89","1.60","1.470","0.01500"
"58.39","1.57","1.252","0.01488"
"58.89","1.54","1.044","0.01476"
"59.00","1.53","0.9996","0.01474"
"59.00","1.53","0.9987","0.01474"
"59.01","1.53","0.9979","0.01474"
"59.51","1.56","1.675","0.01499"
"60.01","1.60","2.372","0.01527"
"60.51","1.63","3.039","0.01554"
"61.01","1.66","3.635","0.01579"
"61.51","1.70","4.085","0.01597"
"62.01","1.73","4.529","0.01615"
"62.51","1.76","4.978","0.01633"
"63.01","1.80","5.429","0.01652"
"63.51","1.83","5.869","0.01669"
"64.01","1.86","6.292","0.01688"
"64.51","1.90","6.685","0.01703"
"65.01","1.93","7.051","0.01720"
"65.51","1.96","7.407","0.01735"
"66.01","2.00","7.738","0.01746"
"66.51","2.03","8.104","0.01762"
"67.01","2.06","8.465","0.01779"
"67.51","2.10","8.819","0.01796"
"68.01","2.13","9.172","0.01812"
"68.51","2.16","9.522","0.01828"
"69.01","2.20","9.869","0.01845"
"69.51","2.23","10.22","0.01862"
"70.01","2.26","10.56","0.01878"
"70.51","2.30","10.90","0.01895"
"71.01","2.33","11.24","0.01912"
"71.51","2.36","11.56","0.01930"
"72.01","2.40","11.88","0.01947"
"72.51","2.43","12.19","0.01964"
"73.01","2.46","12.47","0.01982"
"73.51","2.50","12.74","0.02000"
"74.01","2.53","12.98","0.02020"
"74.51","2.56","13.15","0.02047"
"75.01","2.60","13.10","0.02085"
"75.51","2.63","13.08","0.02128"
"76.01","2.66","13.07","0.02202"
"76.51","2.70","13.08","0.02302"
"77.01","2.73","13.12","0.02408"
"77.51","2.76","13.17","0.02504"
"78.01","2.80","13.20","0.02592"
"78.51","2.83","13.22","0.02652"
"79.01","2.86","13.26","0.02693"
"79.51","2.90","13.31","0.02743"
"80.01","2.93","13.33","0.02817"
"80.51","2.96","13.36","0.02907"
"81.01","3.00","13.40","0.02997"
"81.51","3.03","13.44","0.03081"
"82.01","3.06","13.46","0.03148"
"82.51","3.10","13.49","0.03199"
"83.01","3.13","13.53","0.03248"
"83.51","3.16","13.56","0.03309"
"84.01","3.20","13.58","0.03390"
"84.51","3.23","13.61","0.03483"
"85.01","3.26","13.65","0.03573"
"85.51","3.30","13.68","0.03659"
"86.01","3.33","13.70","0.03729"
"86.51","3.36","13.72","0.03779"
"87.01","3.40","13.76","0.03820"
"87.51","3.43","13.80","0.03868"
"88.01","3.46","13.82","0.03934"
"88.51","3.50","13.84","0.04022"
"89.01","3.53","13.85","0.04124"
"89.51","3.56","13.90","0.04224"
"90.01","3.60","13.94","0.04320"
"90.51","3.63","13.96","0.04397"
"91.01","3.66","13.96","0.04459"
"91.51","3.70","13.97","0.04505"
"92.01","3.73","14.01","0.04546"
"92.51","3.76","14.06","0.04589"
"93.01","3.80","14.08","0.04652"
"93.51","3.83","14.10","0.04729"
"94.01","3.86","14.12","0.04822"
"94.51","3.90","14.14","0.04924"
"95.01","3.93","14.13","0.05032"
"95.51","3.96","14.18","0.05119"
"96.01","4.00","14.24","0.05183"
"96.51","4.03","14.26","0.05225"
"97.01","4.06","14.31","0.05255"
"97.51","4.10","14.26","0.05282"
"98.01","4.13","14.28","0.05328"
"98.51","4.16","14.31","0.05414"
"99.01","4.20","14.33","0.05520"
"99.51","4.23","14.34","0.05632"
"100.01","4.26","14.38","0.05745"
"100.51","4.30","14.42","0.05854"
"101.01","4.33","14.45","0.05968"
"101.51","4.36","14.46","0.06066"
"102.01","4.40","14.48","0.06133"
"102.51","4.43","14.51","0.06167"
"103.01","4.46","14.51","0.06181"
"103.51","4.50","14.53","0.06194"
"104.01","4.53","14.53","0.06211"
"104.51","4.56","14.54","0.06268"
"105.01","4.60","14.56","0.06359"
"105.51","4.63","14.59","0.06466"
"106.01","4.66","14.62","0.06579"
"106.51","4.70","14.64","0.06692"
"107.01","4.73","14.66","0.06807"
"107.51","4.76","14.68","0.06923"
"108.01","4.80","14.70","0.07038"
"108.51","4.83","14.72","0.07138"
"109.01","4.86","14.74","0.07204"
"109.51","4.90","14.77","0.07236"
"110.01","4.93","14.76","0.07250"
"110.51","4.96","14.85","0.07262"
"111.01","5.00","14.82","0.07275"
"111.51","5.03","14.78","0.07284"
"112.01","5.06","14.79","0.07329"
"112.51","5.10","14.82","0.07408"
"113.01","5.13","14.84","0.07509"
"113.51","5.16","14.86","0.07620"
"114.01","5.20","14.88","0.07735"
"114.51","5.23","14.90","0.07853"
"115.01","5.26","14.92","0.07971"
"115.13","5.27","14.92","0.08000"
"115.13","5.27","14.92","0.08001"
"115.19","5.28","14.93","0.08014"
"115.69","5.24","14.15","0.08013"
"116.19","5.21","13.41","0.07980"
"116.69","5.18","12.72","0.07948"
"117.19","5.14","12.06","0.07917"
"117.69","5.11","11.42","0.07885"
"118.19","5.08","10.77","0.07853"
"118.69","5.04","10.13","0.07822"
"119.19","5.01","9.504","0.07790"
"119.69","4.98","8.882","0.07758"
"120.19","4.94","8.261","0.07725"
"120.69","4.91","7.648","0.07692"
"121.19","4.88","7.047","0.07659"
"121.69","4.84","6.465","0.07626"
"122.19","4.81","5.933","0.07596"
"122.69","4.78","5.524","0.07571"
"123.19","4.74","5.249","0.07555"
"123.69","4.71","5.012","0.07540"
"124.19","4.68","4.779","0.07526"
"124.69","4.64","4.549","0.07512"
"125.19","4.61","4.326","0.07498"
"125.69","4.58","4.104","0.07484"
"126.19","4.54","3.888","0.07472"
"126.69","4.51","3.675","0.07458"
"127.19","4.48","3.465","0.07445"
"127.69","4.44","3.262","0.07432"
"128.19","4.41","3.062","0.07419"
"128.69","4.38","2.870","0.07407"
"129.19","4.34","2.681","0.07395"
"129.69","4.31","2.497","0.07382"
"130.19","4.28","2.318","0.07372"
"130.69","4.24","2.145","0.07358"
"131.19","4.21","1.978","0.07346"
"131.69","4.18","1.805","0.07336"
"132.19","4.14","1.588","0.07322"
"132.69","4.11","1.378","0.07307"
"133.19","4.08","1.178","0.07292"
"133.65","4.04","0.9998","0.07280"
"133.65","4.04","0.9990","0.07280"
"133.66","4.04","0.9982","0.07280"
"134.16","4.08","1.652","0.07306"
"134.66","4.11","2.315","0.07337"
"135.16","4.15","2.958","0.07368"
"135.66","4.18","3.575","0.07397"
"136.16","4.21","4.054","0.07419"
"136.66","4.24","4.489","0.07439"
"137.16","4.28","4.919","0.07458"
"137.66","4.31","5.348","0.07479"
"138.16","4.34","5.760","0.07500"
"138.66","4.38","6.141","0.07518"
"139.16","4.41","6.491","0.07536"
"139.66","4.44","6.838","0.07553"
"140.16","4.48","7.184","0.07571"
"140.66","4.51","7.533","0.07588"
"141.16","4.54","7.880","0.07605"
"141.66","4.58","8.220","0.07624"
"142.16","4.61","8.565","0.07641"
"142.66","4.64","8.912","0.07659"
"143.16","4.68","9.252","0.07678"
"143.66","4.71","9.594","0.07697"
"144.16","4.74","9.928","0.07714"
"144.66","4.78","10.27","0.07733"
"145.16","4.81","10.60","0.07752"
"145.66","4.84","10.93","0.07772"
"146.16","4.88","11.26","0.07789"
"146.66","4.91","11.59","0.07809"
"147.16","4.94","11.92","0.07828"
"147.66","4.98","12.24","0.07847"
"148.16","5.01","12.56","0.07866"
"148.66","5.04","12.88","0.07886"
"149.16","5.08","13.20","0.07907"
"149.66","5.11","13.52","0.07927"
"150.16","5.14","13.82","0.07948"
"150.66","5.18","14.11","0.07968"
"151.16","5.21","14.39","0.07989"
"151.66","5.25","14.66","0.08011"
"152.16","5.28","14.91","0.08032"
"152.66","5.31","15.11","0.08060"
"153.16","5.35","14.97","0.08155"
"153.66","5.38","14.97","0.08265"
"154.16","5.41","14.99","0.08361"
"154.66","5.45","15.01","0.08437"
"155.16","5.48","15.03","0.08492"
"155.66","5.51","15.06","0.08531"
"156.16","5.54","15.07","0.08561"
"156.66","5.58","15.07","0.08583"
"157.16","5.61","15.12","0.08609"
"157.66","5.64","15.10","0.08689"
"158.16","5.68","15.11","0.08799"
"158.66","5.71","15.12","0.08914"
"159.16","5.74","15.11","0.09036"
"159.66","5.78","15.10","0.09159"
"160.16","5.81","15.09","0.09285"
"160.66","5.84","15.07","0.09411"
"161.16","5.88","15.06","0.09520"
"161.66","5.91","15.05","0.09597"
"162.16","5.94","15.03","0.09636"
"162.66","5.98","15.03","0.09650"
"163.16","6.01","15.11","0.09663"
"163.66","6.04","15.18","0.09684"
"164.16","6.08","15.22","0.09728"
"164.66","6.11","15.25","0.09802"
"165.16","6.14","15.27","0.09899"
"165.66","6.18","15.29","0.1001"
"166.16","6.21","15.30","0.1012"
"166.66","6.24","15.32","0.1024"
"167.16","6.28","15.33","0.1036"
"167.66","6.31","15.33","0.1048"
"168.16","6.34","15.29","0.1061"
"168.66","6.38","15.27","0.1073"
"169.16","6.41","15.28","0.1084"
"169.66","6.45","15.30","0.1091"
"170.16","6.48","15.32","0.1095"
"170.66","6.51","15.34","0.1097"
"171.16","6.55","15.33","0.1098"
"171.66","6.58","15.38","0.1099"
"172.16","6.61","15.47","0.1100"
"172.66","6.65","15.50","0.1102"
"173.16","6.68","15.50","0.1106"
"173.66","6.71","15.49","0.1115"
"174.16","6.74","15.49","0.1126"
"174.66","6.78","15.50","0.1137"
"175.16","6.81","15.52","0.1149"
"175.66","6.84","15.53","0.1161"
"176.16","6.88","15.53","0.1173"
"176.66","6.91","15.53","0.1186"
"177.16","6.94","15.52","0.1198"
"177.66","6.98","15.51","0.1211"
"178.16","7.01","15.49","0.1224"
"178.66","7.04","15.48","0.1236"
"179.16","7.08","15.46","0.1245"
"179.66","7.11","15.46","0.1250"
"180.16","7.14","15.43","0.1253"
"180.66","7.18","15.45","0.1254"
"181.16","7.21","15.54","0.1255"
"181.66","7.24","15.59","0.1257"
"182.16","7.28","15.62","0.1261"
"182.66","7.31","15.63","0.1269"
"183.16","7.34","15.64","0.1278"
"183.66","7.38","15.65","0.1290"
"184.16","7.41","15.66","0.1301"
"184.66","7.44","15.67","0.1313"
"185.16","7.48","15.68","0.1326"
"185.66","7.51","15.69","0.1338"
"186.16","7.54","15.69","0.1351"
"186.66","7.58","15.70","0.1363"
"187.16","7.61","15.69","0.1375"
"187.66","7.64","15.69","0.1388"
"188.16","7.68","15.68","0.1401"
"188.66","7.71","15.68","0.1413"
"189.16","7.74","15.67","0.1424"
"189.66","7.78","15.68","0.1433"
"190.16","7.81","15.68","0.1439"
"190.66","7.84","15.69","0.1442"
"191.16","7.88","15.69","0.1443"
"191.66","7.91","15.69","0.1444"
"192.16","7.94","15.70","0.1445"
"192.66","7.98","15.78","0.1445"
"193.16","8.01","15.83","0.1446"
"193.66","8.05","15.85","0.1447"
"194.16","8.08","15.85","0.1450"
"194.66","8.11","15.85","0.1457"
"195.16","8.15","15.84","0.1466"
"195.66","8.18","15.84","0.1477"
"196.16","8.21","15.84","0.1489"
"196.66","8.24","15.84","0.1501"
"197.16","8.28","15.83","0.1514"
"197.66","8.31","15.83","0.1526"
"198.16","8.34","15.82","0.1539"
"198.66","8.38","15.82","0.1552"
"199.16","8.41","15.81","0.1565"
"199.66","8.45","15.80","0.1577"
"200.16","8.48","15.80","0.1590"
"200.66","8.51","15.79","0.1603"
"201.16","8.54","15.78","0.1616"
"201.66","8.58","15.78","0.1629"
"202.16","8.61","15.77","0.1641"
"202.66","8.64","15.77","0.1653"
"203.16","8.68","15.77","0.1664"
"203.66","8.71","15.77","0.1673"
"204.16","8.74","15.77","0.1680"
"204.66","8.78","15.78","0.1684"
"205.16","8.81","15.78","0.1687"
"205.66","8.84","15.78","0.1689"
"206.16","8.88","15.81","0.1689"
"206.66","8.91","15.88","0.1690"
"207.16","8.94","15.89","0.1693"
"207.66","8.98","15.87","0.1698"
"208.16","9.01","15.86","0.1707"
"208.66","9.04","15.84","0.1719"
"209.16","9.08","15.84","0.1731"
"209.66","9.11","15.83","0.1743"
"210.16","9.14","15.83","0.1756"
"210.66","9.18","15.83","0.1768"
"211.16","9.21","15.83","0.1781"
"211.66","9.25","15.83","0.1794"
"212.16","9.28","15.83","0.1807"
"212.66","9.31","15.83","0.1820"
"213.16","9.34","15.83","0.1833"
"213.66","9.38","15.83","0.1845"
"214.16","9.41","15.83","0.1858"
"214.66","9.44","15.83","0.1871"
"215.16","9.48","15.82","0.1884"
"215.66","9.51","15.81","0.1897"
"216.16","9.55","15.80","0.1910"
"216.66","9.58","15.79","0.1923"
"217.16","9.61","15.78","0.1936"
"217.66","9.65","15.77","0.1949"
"218.16","9.68","15.76","0.1962"
"218.66","9.71","15.75","0.1975"
"219.16","9.74","15.73","0.1988"
"219.66","9.78","15.72","0.2001"
"220.16","9.81","15.70","0.2014"
"220.66","9.84","15.69","0.2027"
"221.16","9.88","15.67","0.2040"
"221.66","9.91","15.65","0.2053"
"222.16","9.94","15.63","0.2067"
"222.66","9.98","15.61","0.2080"
"223.16","10.01","15.59","0.2093"
"223.66","10.04","15.57","0.2106"
"224.16","10.08","15.54","0.2119"
"224.66","10.11","15.52","0.2133"
"225.16","10.14","15.50","0.2146"
"225.66","10.18","15.47","0.2159"
"226.16","10.21","15.45","0.2172"
"226.66","10.24","15.42","0.2185"
"227.16","10.28","15.39","0.2199"
"227.66","10.31","15.36","0.2212"
"228.16","10.34","15.33","0.2225"
"228.66","10.38","15.29","0.2239"
"229.16","10.41","15.26","0.2252"
"229.66","10.44","15.23","0.2265"
"230.16","10.48","15.19","0.2279"
"230.66","10.51","15.16","0.2292"
"231.16","10.54","15.12","0.2305"
"231.66","10.58","15.08","0.2319"
"232.16","10.61","15.04","0.2332"
"232.66","10.64","15.00","0.2346"
"233.16","10.68","14.96","0.2359"
"233.66","10.71","14.92","0.2373"
"234.16","10.74","14.87","0.2386"
"234.66","10.78","14.83","0.2400"
"235.16","10.81","14.78","0.2414"
"235.66","10.84","14.73","0.2427"
"236.16","10.88","14.69","0.2441"
"236.66","10.91","14.64","0.2455"
"237.16","10.95","14.59","0.2468"
"237.66","10.98","14.53","0.2482"
"238.16","11.01","14.48","0.2496"
"238.66","11.05","14.42","0.2509"
"239.16","11.08","14.37","0.2523"
"239.66","11.11","14.31","0.2537"
"240.16","11.14","14.25","0.2551"
"240.66","11.18","14.19","0.2565"
"241.16","11.21","14.13","0.2578"
"241.66","11.24","14.07","0.2592"
"242.16","11.28","14.00","0.2606"
"242.66","11.31","13.94","0.2620"
"243.16","11.34","13.87","0.2634"
"243.66","11.38","13.80","0.2648"
"244.16","11.41","13.73","0.2662"
"244.66","11.44","13.65","0.2676"
"245.16","11.48","13.58","0.2690"
"245.66","11.51","13.50","0.2704"
"246.16","11.54","13.42","0.2719"
"246.66","11.58","13.34","0.2733"
"247.16","11.61","13.26","0.2747"
"247.66","11.64","13.17","0.2761"
"248.16","11.68","13.08","0.2776"
"248.66","11.71","12.99","0.2790"
"249.16","11.74","12.89","0.2804"
"249.66","11.78","12.79","0.2819"
"250.16","11.81","12.67","0.2834"
"250.22","11.82","7.007","0.2952"