File: Lab2/data/N02D304_1.csv
System ID,,"4483C1713"
Method name only,,"Tension_Round_NEW"
Test type,,"Tension"
Sample file name,,"N02D304"
Last test date,,"Monday, September 16, 2024"
Last test time,,"5:19:06 PM"
Course,,"NPRE 432"
Lab Section Number,,"02"
Group,,"D"
Material,,"304"
Heat Treatment,,""
Other Information,,""
Crosshead Speed,(mm/min),"4.00"
Geometry,,"Circular"
Gage Diameter,(mm),"7.20"
Grip Diameter,(mm),"12.88"
Rockwell Hardness,,"100.6"
Rockwell Scale,,"HRB"
Extensometer Gage Length,(mm),"25.40"
Final Gage Diameter,(mm),"3.87"
Fracture Notes and Location,,"VERY DUCTILE CUP CONE STRUCTURE. SAMPLE BECAME MAGNETIC AT FAIL SURFACE WHERE IT WASN'T BEFORE"
Notes During Test,,""

Results Table 1
,,"1"
Maximum Force,(kN),"28.78"
Maximum Strain,(%),"50.26"

Time,Displacement,Force,Strain 1
(s),(mm),(kN),(mm/mm)
"0.00","0.00","0.08339","-0.00001061"
"0.50","0.03","0.8291","-0.00003859"
"1.00","0.07","1.104","-0.00003332"
"1.50","0.10","1.296","-0.00003831"
"2.00","0.13","1.462","-0.00001585"
"2.50","0.17","1.621","-0.00002221"
"3.00","0.20","1.758","-0.00002726"
"3.50","0.23","1.886","-0.00002552"
"4.00","0.27","2.009","-0.00003432"
"4.50","0.30","2.139","-0.00003297"
"5.00","0.33","2.284","-0.00002742"
"5.50","0.37","2.432","-0.00002809"
"6.00","0.40","2.583","-0.00003992"
"6.50","0.43","2.742","-0.00004967"
"7.00","0.47","2.900","-0.00003531"
"7.50","0.50","3.058","-0.00001565"
"8.00","0.53","3.218","0.00007311"
"8.50","0.57","3.373","0.00006561"
"9.00","0.60","3.523","0.00005561"
"9.50","0.63","3.675","0.00007609"
"10.00","0.67","3.832","0.00005609"
"10.50","0.70","3.987","0.00004915"
"11.00","0.73","4.147","0.00003900"
"11.50","0.77","4.305","0.00005463"
"12.00","0.80","4.465","0.00004308"
"12.50","0.83","4.633","0.00004598"
"13.00","0.87","4.794","0.00003812"
"13.50","0.90","4.962","0.00003206"
"14.00","0.93","5.134","0.00005199"
"14.50","0.97","5.303","0.00004316"
"15.00","1.00","5.474","0.00003792"
"15.50","1.03","5.653","0.00004808"
"16.00","1.07","5.834","0.00005000"
"16.50","1.10","6.022","0.00005624"
"17.00","1.13","6.219","0.00006776"
"17.50","1.17","6.408","0.00006059"
"18.00","1.20","6.608","0.00006341"
"18.50","1.23","6.809","0.00008409"
"19.00","1.27","7.006","0.0001020"
"19.50","1.30","7.214","0.0001079"
"20.00","1.33","7.418","0.0001154"
"20.50","1.37","7.630","0.0001252"
"21.00","1.40","7.856","0.0001237"
"21.50","1.43","8.075","0.0001530"
"22.00","1.47","8.302","0.0001603"
"22.50","1.50","8.531","0.0001490"
"23.00","1.53","8.757","0.0001679"
"23.50","1.57","8.991","0.0001651"
"24.00","1.60","9.230","0.0001630"
"24.50","1.63","9.465","0.0001567"
"25.00","1.67","9.706","0.0001593"
"25.50","1.70","9.956","0.0001726"
"26.00","1.73","10.20","0.0001698"
"26.50","1.77","10.45","0.0001741"
"27.00","1.80","10.70","0.0001810"
"27.50","1.83","10.95","0.0001824"
"28.00","1.87","11.20","0.0001987"
"28.50","1.90","11.46","0.0002095"
"29.00","1.93","11.71","0.0002127"
"29.50","1.97","11.98","0.0002262"
"30.00","2.00","12.24","0.0002346"
"30.50","2.03","12.50","0.0002449"
"31.00","2.07","12.77","0.0002570"
"31.50","2.10","13.04","0.0002771"
"32.00","2.13","13.31","0.0002965"
"32.50","2.17","13.59","0.0003593"
"33.00","2.20","13.86","0.0003485"
"33.50","2.23","14.13","0.0003438"
"34.00","2.27","14.42","0.0003615"
"34.50","2.30","14.69","0.0003798"
"35.00","2.33","14.97","0.0004139"
"35.50","2.37","15.26","0.0004181"
"36.00","2.40","15.53","0.0004433"
"36.50","2.43","15.81","0.0004761"
"37.00","2.47","16.08","0.0004934"
"37.50","2.50","16.36","0.0005077"
"38.00","2.53","16.64","0.0005198"
"38.50","2.57","16.91","0.0005420"
"39.00","2.60","17.19","0.0005565"
"39.50","2.63","17.46","0.0005693"
"40.00","2.67","17.74","0.0005948"
"40.50","2.70","18.00","0.0006255"
"41.00","2.73","18.28","0.0007528"
"41.50","2.77","18.55","0.0008597"
"42.00","2.80","18.81","0.001003"
"42.50","2.83","19.07","0.001130"
"43.00","2.87","19.33","0.001271"
"43.50","2.90","19.57","0.001343"
"44.00","2.93","19.83","0.001488"
"44.50","2.97","20.07","0.001671"
"45.00","3.00","20.32","0.001828"
"45.50","3.03","20.56","0.002026"
"46.00","3.07","20.80","0.002197"
"46.50","3.10","21.03","0.002432"
"47.00","3.13","21.25","0.002637"
"47.50","3.17","21.46","0.002864"
"48.00","3.20","21.67","0.003139"
"48.50","3.23","21.87","0.003404"
"49.00","3.27","22.05","0.003685"
"49.50","3.30","22.22","0.003995"
"50.00","3.33","22.38","0.004364"
"50.50","3.37","22.53","0.004697"
"51.00","3.40","22.66","0.005092"
"51.50","3.43","22.78","0.005532"
"52.00","3.47","22.89","0.005968"
"52.50","3.50","22.99","0.006450"
"53.00","3.53","23.07","0.006960"
"53.50","3.57","23.15","0.007457"
"54.00","3.60","23.22","0.008024"
"54.50","3.63","23.27","0.008580"
"55.00","3.67","23.34","0.009160"
"55.50","3.70","23.39","0.009753"
"56.00","3.73","23.43","0.01036"
"56.50","3.77","23.48","0.01099"
"57.00","3.80","23.52","0.01163"
"57.50","3.83","23.56","0.01226"
"58.00","3.87","23.60","0.01288"
"58.50","3.90","23.64","0.01354"
"59.00","3.93","23.67","0.01417"
"59.50","3.97","23.71","0.01482"
"60.00","4.00","23.73","0.01550"
"60.50","4.03","23.76","0.01614"
"61.00","4.07","23.80","0.01681"
"61.50","4.10","23.83","0.01746"
"62.00","4.13","23.86","0.01812"
"62.50","4.17","23.89","0.01878"
"63.00","4.20","23.92","0.01944"
"63.50","4.23","23.94","0.02009"
"64.00","4.27","23.97","0.02079"
"64.50","4.30","24.00","0.02142"
"65.00","4.33","24.02","0.02209"
"65.50","4.37","24.05","0.02275"
"66.00","4.40","24.08","0.02342"
"66.50","4.43","24.11","0.02408"
"67.00","4.47","24.13","0.02472"
"67.50","4.50","24.15","0.02538"
"68.00","4.53","24.19","0.02601"
"68.50","4.57","24.21","0.02668"
"69.00","4.60","24.23","0.02733"
"69.50","4.63","24.26","0.02800"
"70.00","4.67","24.28","0.02867"
"70.50","4.70","24.31","0.02930"
"71.00","4.73","24.33","0.02995"
"71.50","4.77","24.35","0.03059"
"72.00","4.80","24.38","0.03125"
"72.50","4.83","24.40","0.03191"
"73.00","4.87","24.43","0.03256"
"73.50","4.90","24.45","0.03321"
"74.00","4.93","24.48","0.03387"
"74.50","4.97","24.49","0.03449"
"75.00","5.00","24.52","0.03515"
"75.50","5.03","24.54","0.03580"
"76.00","5.07","24.56","0.03645"
"76.50","5.10","24.59","0.03710"
"77.00","5.13","24.61","0.03773"
"77.50","5.17","24.63","0.03838"
"78.00","5.20","24.65","0.03903"
"78.50","5.23","24.67","0.03967"
"79.00","5.27","24.69","0.04032"
"79.50","5.30","24.72","0.04093"
"80.00","5.33","24.73","0.04157"
"80.50","5.37","24.75","0.04221"
"81.00","5.40","24.77","0.04284"
"81.50","5.43","24.79","0.04348"
"82.00","5.47","24.82","0.04412"
"82.50","5.50","24.84","0.04478"
"83.00","5.53","24.85","0.04540"
"83.50","5.57","24.87","0.04604"
"84.00","5.60","24.90","0.04668"
"84.50","5.63","24.91","0.04731"
"85.00","5.67","24.93","0.04795"
"85.50","5.70","24.95","0.04858"
"86.00","5.73","24.97","0.04921"
"86.50","5.77","24.99","0.04986"
"87.00","5.80","25.01","0.05049"
"87.50","5.83","25.03","0.05113"
"88.00","5.87","25.05","0.05175"
"88.50","5.90","25.06","0.05241"
"89.00","5.93","25.09","0.05302"
"89.50","5.97","25.11","0.05365"
"90.00","6.00","25.12","0.05425"
"90.50","6.03","25.15","0.05487"
"91.00","6.07","25.17","0.05551"
"91.50","6.10","25.18","0.05615"
"92.00","6.13","25.20","0.05678"
"92.50","6.17","25.22","0.05741"
"93.00","6.20","25.23","0.05803"
"93.50","6.23","25.26","0.05867"
"94.00","6.27","25.28","0.05930"
"94.50","6.30","25.29","0.05993"
"95.00","6.33","25.32","0.06057"
"95.50","6.37","25.33","0.06119"
"96.00","6.40","25.35","0.06181"
"96.50","6.43","25.37","0.06243"
"97.00","6.47","25.39","0.06308"
"97.50","6.50","25.41","0.06370"
"98.00","6.53","25.42","0.06431"
"98.50","6.57","25.44","0.06494"
"99.00","6.60","25.46","0.06557"
"99.50","6.63","25.48","0.06618"
"100.00","6.67","25.49","0.06680"
"100.50","6.70","25.51","0.06744"
"101.00","6.73","25.53","0.06806"
"101.50","6.77","25.54","0.06870"
"102.00","6.80","25.56","0.06931"
"102.50","6.83","25.58","0.06992"
"103.00","6.87","25.59","0.07055"
"103.50","6.90","25.61","0.07117"
"104.00","6.93","25.62","0.07180"
"104.50","6.97","25.64","0.07241"
"105.00","7.00","25.66","0.07303"
"105.50","7.03","25.68","0.07366"
"106.00","7.07","25.69","0.07429"
"106.50","7.10","25.71","0.07490"
"107.00","7.13","25.73","0.07551"
"107.50","7.17","25.74","0.07615"
"108.00","7.20","25.75","0.07677"
"108.50","7.23","25.77","0.07742"
"109.00","7.27","25.79","0.07800"
"109.50","7.30","25.81","0.07866"
"110.00","7.33","25.81","0.07925"
"110.50","7.37","25.84","0.07988"
"111.00","7.40","25.85","0.08050"
"111.50","7.43","25.87","0.08111"
"112.00","7.47","25.89","0.08176"
"112.50","7.50","25.90","0.08239"
"113.00","7.53","25.92","0.08299"
"113.50","7.57","25.94","0.08361"
"114.00","7.60","25.95","0.08424"
"114.50","7.63","25.96","0.08484"
"115.00","7.67","25.98","0.08548"
"115.50","7.70","25.99","0.08609"
"116.00","7.73","26.01","0.08674"
"116.50","7.77","26.03","0.08734"
"117.00","7.80","26.05","0.08796"
"117.50","7.83","26.06","0.08859"
"118.00","7.87","26.08","0.08923"
"118.50","7.90","26.09","0.08986"
"119.00","7.93","26.11","0.09048"
"119.50","7.97","26.12","0.09109"
"120.00","8.00","26.13","0.09174"
"120.50","8.03","26.15","0.09234"
"121.00","8.07","26.17","0.09298"
"121.50","8.10","26.18","0.09358"
"122.00","8.13","26.20","0.09424"
"122.50","8.17","26.21","0.09485"
"123.00","8.20","26.22","0.09545"
"123.50","8.23","26.24","0.09609"
"124.00","8.27","26.25","0.09670"
"124.50","8.30","26.26","0.09733"
"125.00","8.33","26.28","0.09797"
"125.50","8.37","26.29","0.09858"
"126.00","8.40","26.31","0.09924"
"126.50","8.43","26.33","0.09984"
"127.00","8.47","26.33","0.1005"
"127.50","8.50","26.35","0.1011"
"128.00","8.53","26.36","0.1017"
"128.50","8.57","26.37","0.1023"
"129.00","8.60","26.39","0.1030"
"129.50","8.63","26.40","0.1036"
"130.00","8.67","26.42","0.1042"
"130.50","8.70","26.43","0.1048"
"131.00","8.73","26.44","0.1055"
"131.50","8.77","26.45","0.1061"
"132.00","8.80","26.47","0.1067"
"132.50","8.83","26.49","0.1073"
"133.00","8.87","26.50","0.1079"
"133.50","8.90","26.52","0.1085"
"134.00","8.93","26.53","0.1092"
"134.50","8.97","26.54","0.1098"
"135.00","9.00","26.55","0.1104"
"135.50","9.03","26.56","0.1111"
"136.00","9.07","26.59","0.1117"
"136.50","9.10","26.60","0.1123"
"137.00","9.13","26.60","0.1129"
"137.50","9.17","26.62","0.1136"
"138.00","9.20","26.63","0.1142"
"138.50","9.23","26.65","0.1148"
"139.00","9.27","26.67","0.1154"
"139.50","9.30","26.68","0.1160"
"140.00","9.33","26.69","0.1167"
"140.50","9.37","26.70","0.1173"
"141.00","9.40","26.72","0.1179"
"141.50","9.43","26.72","0.1186"
"142.00","9.47","26.74","0.1192"
"142.50","9.50","26.75","0.1198"
"143.00","9.53","26.76","0.1204"
"143.50","9.57","26.78","0.1211"
"144.00","9.60","26.79","0.1217"
"144.50","9.63","26.81","0.1223"
"145.00","9.67","26.81","0.1230"
"145.50","9.70","26.82","0.1236"
"146.00","9.73","26.84","0.1242"
"146.50","9.77","26.85","0.1249"
"147.00","9.80","26.86","0.1255"
"147.50","9.83","26.87","0.1261"
"148.00","9.87","26.88","0.1268"
"148.50","9.90","26.89","0.1273"
"149.00","9.93","26.91","0.1280"
"149.50","9.97","26.92","0.1286"
"150.00","10.00","26.93","0.1292"
"150.50","10.03","26.95","0.1298"
"151.00","10.07","26.95","0.1305"
"151.50","10.10","26.96","0.1311"
"152.00","10.13","26.98","0.1318"
"152.50","10.17","26.99","0.1324"
"153.00","10.20","27.00","0.1330"
"153.50","10.23","27.01","0.1336"
"154.00","10.27","27.02","0.1343"
"154.50","10.30","27.04","0.1349"
"155.00","10.33","27.05","0.1355"
"155.50","10.37","27.06","0.1361"
"156.00","10.40","27.07","0.1368"
"156.50","10.43","27.09","0.1374"
"157.00","10.47","27.09","0.1380"
"157.50","10.50","27.11","0.1386"
"158.00","10.53","27.12","0.1393"
"158.50","10.57","27.13","0.1399"
"159.00","10.60","27.15","0.1405"
"159.50","10.63","27.16","0.1412"
"160.00","10.67","27.17","0.1418"
"160.50","10.70","27.18","0.1424"
"161.00","10.73","27.18","0.1431"
"161.50","10.77","27.19","0.1437"
"162.00","10.80","27.21","0.1443"
"162.50","10.83","27.22","0.1449"
"163.00","10.87","27.23","0.1456"
"163.50","10.90","27.24","0.1462"
"164.00","10.93","27.25","0.1468"
"164.50","10.97","27.26","0.1475"
"165.00","11.00","27.28","0.1481"
"165.50","11.03","27.28","0.1487"
"166.00","11.07","27.30","0.1493"
"166.50","11.10","27.31","0.1500"
"167.00","11.13","27.31","0.1506"
"167.50","11.17","27.33","0.1512"
"168.00","11.20","27.33","0.1519"
"168.50","11.23","27.35","0.1525"
"169.00","11.27","27.36","0.1531"
"169.50","11.30","27.36","0.1538"
"170.00","11.33","27.38","0.1544"
"170.50","11.37","27.38","0.1550"
"171.00","11.40","27.39","0.1557"
"171.50","11.43","27.40","0.1563"
"172.00","11.47","27.41","0.1569"
"172.50","11.50","27.42","0.1576"
"173.00","11.53","27.43","0.1582"
"173.50","11.57","27.44","0.1589"
"174.00","11.60","27.45","0.1595"
"174.50","11.63","27.46","0.1601"
"175.00","11.67","27.48","0.1608"
"175.50","11.70","27.48","0.1614"
"176.00","11.73","27.50","0.1621"
"176.50","11.77","27.51","0.1627"
"177.00","11.80","27.51","0.1633"
"177.50","11.83","27.53","0.1640"
"178.00","11.87","27.53","0.1646"
"178.50","11.90","27.54","0.1653"
"179.00","11.93","27.55","0.1659"
"179.50","11.97","27.56","0.1666"
"180.00","12.00","27.58","0.1672"
"180.50","12.03","27.59","0.1679"
"181.00","12.07","27.59","0.1685"
"181.50","12.10","27.60","0.1691"
"182.00","12.13","27.61","0.1698"
"182.50","12.17","27.62","0.1704"
"183.00","12.20","27.63","0.1711"
"183.50","12.23","27.65","0.1717"
"184.00","12.27","27.65","0.1723"
"184.50","12.30","27.66","0.1730"
"185.00","12.33","27.66","0.1736"
"185.50","12.37","27.67","0.1743"
"186.00","12.40","27.69","0.1749"
"186.50","12.43","27.69","0.1756"
"187.00","12.47","27.70","0.1762"
"187.50","12.50","27.71","0.1769"
"188.00","12.53","27.72","0.1775"
"188.50","12.57","27.73","0.1782"
"189.00","12.60","27.74","0.1788"
"189.50","12.63","27.75","0.1795"
"190.00","12.67","27.75","0.1801"
"190.50","12.70","27.76","0.1808"
"191.00","12.73","27.77","0.1814"
"191.50","12.77","27.78","0.1821"
"192.00","12.80","27.79","0.1827"
"192.50","12.83","27.79","0.1833"
"193.00","12.87","27.81","0.1839"
"193.50","12.90","27.82","0.1842"
"194.00","12.93","27.82","0.1848"
"194.50","12.97","27.83","0.1855"
"195.00","13.00","27.83","0.1861"
"195.50","13.03","27.85","0.1868"
"196.00","13.07","27.85","0.1874"
"196.50","13.10","27.86","0.1881"
"197.00","13.13","27.87","0.1888"
"197.50","13.17","27.88","0.1894"
"198.00","13.20","27.89","0.1901"
"198.50","13.23","27.89","0.1907"
"199.00","13.27","27.90","0.1914"
"199.50","13.30","27.91","0.1921"
"200.00","13.33","27.92","0.1927"
"200.50","13.37","27.93","0.1934"
"201.00","13.40","27.93","0.1940"
"201.50","13.43","27.95","0.1947"
"202.00","13.47","27.95","0.1954"
"202.50","13.50","27.96","0.1960"
"203.00","13.53","27.97","0.1967"
"203.50","13.57","27.98","0.1974"
"204.00","13.60","27.99","0.1980"
"204.50","13.63","28.00","0.1987"
"205.00","13.67","28.00","0.1994"
"205.50","13.70","28.01","0.2001"
"206.00","13.73","28.02","0.2007"
"206.50","13.77","28.02","0.2014"
"207.00","13.80","28.03","0.2021"
"207.50","13.83","28.04","0.2027"
"208.00","13.87","28.04","0.2034"
"208.50","13.90","28.05","0.2041"
"209.00","13.93","28.06","0.2047"
"209.50","13.97","28.06","0.2054"
"210.00","14.00","28.07","0.2061"
"210.50","14.03","28.08","0.2067"
"211.00","14.07","28.08","0.2074"
"211.50","14.10","28.10","0.2081"
"212.00","14.13","28.10","0.2088"
"212.50","14.17","28.10","0.2094"
"213.00","14.20","28.12","0.2101"
"213.50","14.23","28.12","0.2108"
"214.00","14.27","28.12","0.2115"
"214.50","14.30","28.13","0.2121"
"215.00","14.33","28.14","0.2128"
"215.50","14.37","28.14","0.2135"
"216.00","14.40","28.16","0.2142"
"216.50","14.43","28.15","0.2149"
"217.00","14.47","28.17","0.2156"
"217.50","14.50","28.17","0.2162"
"218.00","14.53","28.17","0.2169"
"218.50","14.57","28.19","0.2176"
"219.00","14.60","28.19","0.2183"
"219.50","14.63","28.20","0.2190"
"220.00","14.67","28.21","0.2196"
"220.50","14.70","28.22","0.2203"
"221.00","14.73","28.22","0.2210"
"221.50","14.77","28.23","0.2217"
"222.00","14.80","28.24","0.2224"
"222.50","14.83","28.24","0.2231"
"223.00","14.87","28.25","0.2238"
"223.50","14.90","28.25","0.2245"
"224.00","14.93","28.26","0.2252"
"224.50","14.97","28.27","0.2259"
"225.00","15.00","28.28","0.2266"
"225.50","15.03","28.28","0.2273"
"226.00","15.07","28.29","0.2279"
"226.50","15.10","28.29","0.2286"
"227.00","15.13","28.30","0.2293"
"227.50","15.17","28.31","0.2300"
"228.00","15.20","28.31","0.2307"
"228.50","15.23","28.32","0.2314"
"229.00","15.27","28.32","0.2321"
"229.50","15.30","28.33","0.2328"
"230.00","15.33","28.34","0.2335"
"230.50","15.37","28.34","0.2342"
"231.00","15.40","28.34","0.2349"
"231.50","15.43","28.36","0.2356"
"232.00","15.47","28.36","0.2363"
"232.50","15.50","28.36","0.2370"
"233.00","15.53","28.37","0.2377"
"233.50","15.57","28.38","0.2384"
"234.00","15.60","28.38","0.2392"
"234.50","15.63","28.39","0.2399"
"235.00","15.67","28.39","0.2406"
"235.50","15.70","28.40","0.2413"
"236.00","15.73","28.40","0.2420"
"236.50","15.77","28.40","0.2427"
"237.00","15.80","28.41","0.2435"
"237.50","15.83","28.41","0.2442"
"238.00","15.87","28.42","0.2449"
"238.50","15.90","28.43","0.2456"
"239.00","15.93","28.43","0.2463"
"239.50","15.97","28.44","0.2470"
"240.00","16.00","28.45","0.2478"
"240.50","16.03","28.45","0.2485"
"241.00","16.07","28.45","0.2492"
"241.50","16.10","28.46","0.2499"
"242.00","16.13","28.46","0.2507"
"242.50","16.17","28.47","0.2514"
"243.00","16.20","28.49","0.2521"
"243.50","16.23","28.48","0.2529"
"244.00","16.27","28.49","0.2536"
"244.50","16.30","28.49","0.2543"
"245.00","16.33","28.50","0.2551"
"245.50","16.37","28.51","0.2558"
"246.00","16.40","28.51","0.2566"
"246.50","16.43","28.51","0.2573"
"247.00","16.47","28.52","0.2580"
"247.50","16.50","28.52","0.2588"
"248.00","16.53","28.53","0.2595"
"248.50","16.57","28.53","0.2602"
"249.00","16.60","28.54","0.2610"
"249.50","16.63","28.54","0.2617"
"250.00","16.67","28.55","0.2625"
"250.50","16.70","28.54","0.2632"
"251.00","16.73","28.55","0.2640"
"251.50","16.77","28.56","0.2647"
"252.00","16.80","28.56","0.2655"
"252.50","16.83","28.57","0.2662"
"253.00","16.87","28.57","0.2670"
"253.50","16.90","28.57","0.2678"
"254.00","16.93","28.58","0.2685"
"254.50","16.97","28.58","0.2693"
"255.00","17.00","28.58","0.2701"
"255.50","17.03","28.59","0.2708"
"256.00","17.07","28.59","0.2716"
"256.50","17.10","28.60","0.2723"
"257.00","17.13","28.60","0.2731"
"257.50","17.17","28.61","0.2739"
"258.00","17.20","28.61","0.2747"
"258.50","17.23","28.61","0.2754"
"259.00","17.27","28.62","0.2762"
"259.50","17.30","28.62","0.2770"
"260.00","17.33","28.62","0.2778"
"260.50","17.37","28.63","0.2785"
"261.00","17.40","28.64","0.2793"
"261.50","17.43","28.64","0.2801"
"262.00","17.47","28.64","0.2809"
"262.50","17.50","28.64","0.2817"
"263.00","17.53","28.65","0.2825"
"263.50","17.57","28.65","0.2832"
"264.00","17.60","28.66","0.2841"
"264.50","17.63","28.67","0.2849"
"265.00","17.67","28.66","0.2856"
"265.50","17.70","28.67","0.2864"
"266.00","17.73","28.67","0.2872"
"266.50","17.77","28.67","0.2880"
"267.00","17.80","28.68","0.2888"
"267.50","17.83","28.68","0.2896"
"268.00","17.87","28.68","0.2905"
"268.50","17.90","28.69","0.2913"
"269.00","17.93","28.68","0.2921"
"269.50","17.97","28.70","0.2929"
"270.00","18.00","28.70","0.2937"
"270.50","18.03","28.70","0.2945"
"271.00","18.07","28.70","0.2953"
"271.50","18.10","28.70","0.2962"
"272.00","18.13","28.71","0.2970"
"272.50","18.17","28.71","0.2978"
"273.00","18.20","28.71","0.2987"
"273.50","18.23","28.71","0.2995"
"274.00","18.27","28.72","0.3003"
"274.50","18.30","28.72","0.3012"
"275.00","18.33","28.72","0.3020"
"275.50","18.37","28.72","0.3028"
"276.00","18.40","28.72","0.3037"
"276.50","18.43","28.72","0.3045"
"277.00","18.47","28.73","0.3054"
"277.50","18.50","28.73","0.3062"
"278.00","18.53","28.73","0.3071"
"278.50","18.57","28.73","0.3079"
"279.00","18.60","28.73","0.3088"
"279.50","18.63","28.74","0.3096"
"280.00","18.67","28.74","0.3105"
"280.50","18.70","28.74","0.3114"
"281.00","18.73","28.74","0.3122"
"281.50","18.77","28.75","0.3131"
"282.00","18.80","28.74","0.3140"
"282.50","18.83","28.75","0.3148"
"283.00","18.87","28.75","0.3157"
"283.50","18.90","28.75","0.3166"
"284.00","18.93","28.76","0.3174"
"284.50","18.97","28.76","0.3106"
"285.00","19.00","28.75","0.3115"
"285.50","19.03","28.77","0.3124"
"286.00","19.07","28.76","0.3133"
"286.50","19.10","28.76","0.3143"
"287.00","19.13","28.76","0.3152"
"287.50","19.17","28.77","0.3161"
"288.00","19.20","28.77","0.3170"
"288.50","19.23","28.77","0.3179"
"289.00","19.27","28.77","0.3189"
"289.50","19.30","28.77","0.3198"
"290.00","19.33","28.78","0.3207"
"290.50","19.37","28.77","0.3217"
"291.00","19.40","28.78","0.3226"
"291.50","19.43","28.77","0.3236"
"292.00","19.47","28.77","0.3245"
"292.50","19.50","28.77","0.3255"
"293.00","19.53","28.77","0.3264"
"293.50","19.57","28.77","0.3274"
"294.00","19.60","28.77","0.3284"
"294.50","19.63","28.76","0.3293"
"295.00","19.67","28.77","0.3303"
"295.50","19.70","28.77","0.3313"
"296.00","19.73","28.77","0.3323"
"296.50","19.77","28.76","0.3333"
"297.00","19.80","28.76","0.3343"
"297.50","19.83","28.76","0.3353"
"298.00","19.87","28.76","0.3363"
"298.50","19.90","28.76","0.3373"
"299.00","19.93","28.76","0.3383"
"299.50","19.97","28.75","0.3393"
"300.00","20.00","28.76","0.3404"
"300.50","20.03","28.75","0.3414"
"301.00","20.07","28.75","0.3425"
"301.50","20.10","28.75","0.3435"
"302.00","20.13","28.75","0.3446"
"302.50","20.17","28.75","0.3456"
"303.00","20.20","28.74","0.3467"
"303.50","20.23","28.74","0.3478"
"304.00","20.27","28.74","0.3489"
"304.50","20.30","28.73","0.3499"
"305.00","20.33","28.73","0.3510"
"305.50","20.37","28.73","0.3521"
"306.00","20.40","28.72","0.3532"
"306.50","20.43","28.71","0.3544"
"307.00","20.47","28.71","0.3555"
"307.50","20.50","28.70","0.3566"
"308.00","20.53","28.70","0.3577"
"308.50","20.57","28.70","0.3589"
"309.00","20.60","28.69","0.3600"
"309.50","20.63","28.68","0.3611"
"310.00","20.67","28.67","0.3623"
"310.50","20.70","28.66","0.3635"
"311.00","20.73","28.66","0.3646"
"311.50","20.77","28.65","0.3658"
"312.00","20.80","28.64","0.3670"
"312.50","20.83","28.63","0.3682"
"313.00","20.87","28.62","0.3694"
"313.50","20.90","28.60","0.3706"
"314.00","20.93","28.59","0.3718"
"314.50","20.97","28.58","0.3730"
"315.00","21.00","28.56","0.3742"
"315.50","21.03","28.55","0.3755"
"316.00","21.07","28.53","0.3767"
"316.50","21.10","28.52","0.3779"
"317.00","21.13","28.50","0.3792"
"317.50","21.17","28.48","0.3804"
"318.00","21.20","28.47","0.3817"
"318.50","21.23","28.44","0.3829"
"319.00","21.27","28.42","0.3842"
"319.50","21.30","28.40","0.3855"
"320.00","21.33","28.38","0.3867"
"320.50","21.37","28.36","0.3880"
"321.00","21.40","28.33","0.3893"
"321.50","21.43","28.30","0.3906"
"322.00","21.47","28.27","0.3919"
"322.50","21.50","28.25","0.3932"
"323.00","21.53","28.22","0.3945"
"323.50","21.57","28.18","0.3958"
"324.00","21.60","28.15","0.3971"
"324.50","21.63","28.12","0.3984"
"325.00","21.67","28.08","0.3997"
"325.50","21.70","28.04","0.4010"
"326.00","21.73","28.00","0.4024"
"326.50","21.77","27.97","0.4037"
"327.00","21.80","27.92","0.4050"
"327.50","21.83","27.87","0.4064"
"328.00","21.87","27.83","0.4077"
"328.50","21.90","27.78","0.4090"
"329.00","21.93","27.74","0.4104"
"329.50","21.97","27.68","0.4117"
"330.00","22.00","27.63","0.4130"
"330.50","22.03","27.57","0.4144"
"331.00","22.07","27.51","0.4158"
"331.50","22.10","27.46","0.4171"
"332.00","22.13","27.39","0.4185"
"332.50","22.17","27.33","0.4198"
"333.00","22.20","27.26","0.4212"
"333.50","22.23","27.19","0.4225"
"334.00","22.27","27.13","0.4239"
"334.50","22.30","27.05","0.4253"
"335.00","22.33","26.98","0.4266"
"335.50","22.37","26.90","0.4280"
"336.00","22.40","26.82","0.4294"
"336.50","22.43","26.74","0.4308"
"337.00","22.47","26.65","0.4322"
"337.50","22.50","26.56","0.4335"
"338.00","22.53","26.47","0.4349"
"338.50","22.57","26.37","0.4363"
"339.00","22.60","26.28","0.4377"
"339.50","22.63","26.18","0.4391"
"340.00","22.67","26.07","0.4405"
"340.50","22.70","25.97","0.4419"
"341.00","22.73","25.86","0.4433"
"341.50","22.77","25.74","0.4447"
"342.00","22.80","25.63","0.4462"
"342.50","22.83","25.52","0.4476"
"343.00","22.87","25.39","0.4490"
"343.50","22.90","25.27","0.4504"
"344.00","22.93","25.14","0.4519"
"344.50","22.97","25.01","0.4533"
"345.00","23.00","24.88","0.4547"
"345.50","23.03","24.74","0.4562"
"346.00","23.07","24.59","0.4576"
"346.50","23.10","24.45","0.4590"
"347.00","23.13","24.30","0.4605"
"347.50","23.17","24.14","0.4619"
"348.00","23.20","23.98","0.4634"
"348.50","23.23","23.83","0.4649"
"349.00","23.27","23.65","0.4664"
"349.50","23.30","23.49","0.4678"
"350.00","23.33","23.30","0.4693"
"350.50","23.37","23.12","0.4708"
"351.00","23.40","22.94","0.4723"
"351.50","23.43","22.74","0.4738"
"352.00","23.47","22.55","0.4753"
"352.50","23.50","22.35","0.4769"
"353.00","23.53","22.13","0.4784"
"353.50","23.57","21.93","0.4799"
"354.00","23.60","21.70","0.4815"
"354.50","23.63","21.47","0.4830"
"355.00","23.67","21.24","0.4846"
"355.50","23.70","21.00","0.4861"
"356.00","23.73","20.75","0.4877"
"356.50","23.77","20.49","0.4893"
"357.00","23.80","20.23","0.4909"
"357.50","23.83","19.95","0.4925"
"358.00","23.87","19.67","0.4941"
"358.50","23.90","19.37","0.4958"
"359.00","23.93","19.06","0.4974"
"359.50","23.97","18.74","0.4991"
"360.00","24.00","18.38","0.5008"
"360.50","24.03","18.03","0.5026"
"360.81","24.05","10.21","0.5007"