File: Lab1/data/N02DPMMA_1.csv
System ID,,"4483C1713"
Method name only,,"Compression_Cylindrical_Plastic_NEW"
Test type,,"Compression"
Sample file name,,"N02DPMMA"
Last test date,,"Monday, September 9, 2024"
Last test time,,"6:04:21 PM"
Course,,"NPRE 432"
Lab Section Number,,"02"
Group,,"D"
Material,,"PMMA"
Other Information,,""
Crosshead Speed,(mm/min),"5.00"
Geometry,,"Circular"
Diameter,(mm),"19.16"
Length,(mm),"65.17"
Final Diameter,,"0.00"
Final Length,,"0.00"
Final Specimen State,,"BARRELED, BUCKLED, CRACKED INTO MANY PIECES"
Notes During Test,,""

Results Table 1
,,"1"
Maximum Force,(kN),"33.30"
Maximum Strain,(%),"48.02"
,,
,,
,,
,,
Time,Displacement,Force,Compressive strain (Displacement)
(s),(mm),(kN),(mm/mm)
"0.00","0.00","0.005082","0.0000"
"0.50","0.04","0.004753","0.0006310"
"1.00","0.08","0.005207","0.001281"
"1.50","0.13","0.1691","0.001920"
"2.00","0.17","0.5761","0.002559"
"2.50","0.21","1.013","0.003199"
"3.00","0.25","1.453","0.003839"
"3.50","0.29","1.881","0.004479"
"4.00","0.33","2.332","0.005117"
"4.50","0.38","2.781","0.005757"
"5.00","0.42","3.241","0.006398"
"5.50","0.46","3.704","0.007036"
"6.00","0.50","4.179","0.007674"
"6.50","0.54","4.669","0.008313"
"7.00","0.58","5.165","0.008954"
"7.50","0.63","5.680","0.009595"
"8.00","0.67","6.204","0.01023"
"8.50","0.71","6.724","0.01087"
"9.00","0.75","7.246","0.01151"
"9.50","0.79","7.773","0.01215"
"10.00","0.83","8.296","0.01279"
"10.50","0.88","8.813","0.01343"
"11.00","0.92","9.330","0.01407"
"11.50","0.96","9.850","0.01471"
"12.00","1.00","10.36","0.01535"
"12.50","1.04","10.87","0.01599"
"13.00","1.08","11.38","0.01663"
"13.50","1.13","11.88","0.01726"
"14.00","1.17","12.38","0.01790"
"14.50","1.21","12.87","0.01855"
"15.00","1.25","13.36","0.01918"
"15.50","1.29","13.84","0.01982"
"16.00","1.33","14.32","0.02046"
"16.50","1.38","14.80","0.02110"
"17.00","1.42","15.27","0.02174"
"17.50","1.46","15.73","0.02238"
"18.00","1.50","16.19","0.02302"
"18.50","1.54","16.64","0.02366"
"19.00","1.58","17.09","0.02430"
"19.50","1.63","17.53","0.02494"
"20.00","1.67","17.96","0.02558"
"20.50","1.71","18.38","0.02622"
"21.00","1.75","18.80","0.02686"
"21.50","1.79","19.21","0.02750"
"22.00","1.83","19.61","0.02813"
"22.50","1.88","20.01","0.02877"
"23.00","1.92","20.40","0.02941"
"23.50","1.96","20.77","0.03005"
"24.00","2.00","21.15","0.03069"
"24.50","2.04","21.49","0.03133"
"25.00","2.08","21.85","0.03197"
"25.50","2.13","22.20","0.03261"
"26.00","2.17","22.55","0.03325"
"26.50","2.21","22.89","0.03389"
"27.00","2.25","23.21","0.03453"
"27.50","2.29","23.53","0.03517"
"28.00","2.33","23.83","0.03581"
"28.50","2.38","24.14","0.03645"
"29.00","2.42","24.43","0.03709"
"29.50","2.46","24.73","0.03772"
"30.00","2.50","25.00","0.03836"
"30.50","2.54","25.27","0.03900"
"31.00","2.58","25.54","0.03964"
"31.50","2.63","25.80","0.04028"
"32.00","2.67","26.05","0.04092"
"32.50","2.71","26.29","0.04156"
"33.00","2.75","26.53","0.04220"
"33.50","2.79","26.76","0.04284"
"34.00","2.83","26.98","0.04348"
"34.50","2.88","27.20","0.04412"
"35.00","2.92","27.41","0.04476"
"35.50","2.96","27.62","0.04540"
"36.00","3.00","27.82","0.04604"
"36.50","3.04","28.01","0.04668"
"37.00","3.08","28.21","0.04732"
"37.50","3.13","28.39","0.04796"
"38.00","3.17","28.54","0.04859"
"38.50","3.21","28.72","0.04923"
"39.00","3.25","28.89","0.04987"
"39.50","3.29","29.05","0.05051"
"40.00","3.33","29.21","0.05115"
"40.50","3.38","29.37","0.05179"
"41.00","3.42","29.51","0.05243"
"41.50","3.46","29.66","0.05307"
"42.00","3.50","29.79","0.05371"
"42.50","3.54","29.93","0.05435"
"43.00","3.58","30.06","0.05499"
"43.50","3.63","30.18","0.05563"
"44.00","3.67","30.31","0.05627"
"44.50","3.71","30.43","0.05691"
"45.00","3.75","30.55","0.05754"
"45.50","3.79","30.67","0.05819"
"46.00","3.83","30.78","0.05882"
"46.50","3.88","30.88","0.05946"
"47.00","3.92","30.98","0.06010"
"47.50","3.96","31.08","0.06074"
"48.00","4.00","31.18","0.06138"
"48.50","4.04","31.27","0.06202"
"49.00","4.08","31.36","0.06266"
"49.50","4.13","31.45","0.06330"
"50.00","4.17","31.54","0.06394"
"50.50","4.21","31.62","0.06458"
"51.00","4.25","31.70","0.06522"
"51.50","4.29","31.78","0.06585"
"52.00","4.33","31.85","0.06649"
"52.50","4.38","31.92","0.06714"
"53.00","4.42","31.99","0.06777"
"53.50","4.46","32.06","0.06841"
"54.00","4.50","32.12","0.06905"
"54.50","4.54","32.18","0.06969"
"55.00","4.58","32.25","0.07033"
"55.50","4.63","32.30","0.07097"
"56.00","4.67","32.35","0.07161"
"56.50","4.71","32.41","0.07225"
"57.00","4.75","32.47","0.07289"
"57.50","4.79","32.52","0.07353"
"58.00","4.83","32.57","0.07417"
"58.50","4.88","32.62","0.07481"
"59.00","4.92","32.66","0.07545"
"59.50","4.96","32.71","0.07609"
"60.00","5.00","32.75","0.07673"
"60.50","5.04","32.79","0.07736"
"61.00","5.08","32.83","0.07800"
"61.50","5.13","32.86","0.07864"
"62.00","5.17","32.89","0.07928"
"62.50","5.21","32.92","0.07992"
"63.00","5.25","32.95","0.08056"
"63.50","5.29","32.98","0.08120"
"64.00","5.33","33.01","0.08184"
"64.50","5.38","33.04","0.08248"
"65.00","5.42","33.05","0.08312"
"65.50","5.46","33.08","0.08376"
"66.00","5.50","33.10","0.08440"
"66.50","5.54","33.12","0.08504"
"67.00","5.58","33.13","0.08568"
"67.50","5.63","33.15","0.08631"
"68.00","5.67","33.16","0.08695"
"68.50","5.71","33.18","0.08759"
"69.00","5.75","33.19","0.08823"
"69.50","5.79","33.20","0.08887"
"70.00","5.83","33.21","0.08951"
"70.50","5.88","33.22","0.09015"
"71.00","5.92","33.23","0.09079"
"71.50","5.96","33.24","0.09143"
"72.00","6.00","33.25","0.09207"
"72.50","6.04","33.25","0.09271"
"73.00","6.08","33.27","0.09335"
"73.50","6.13","33.27","0.09399"
"74.00","6.17","33.28","0.09463"
"74.50","6.21","33.28","0.09527"
"75.00","6.25","33.29","0.09590"
"75.50","6.29","33.29","0.09655"
"76.00","6.33","33.29","0.09718"
"76.50","6.38","33.30","0.09782"
"77.00","6.42","33.30","0.09846"
"77.50","6.46","33.30","0.09910"
"78.00","6.50","33.30","0.09974"
"78.50","6.54","33.30","0.1004"
"79.00","6.58","33.30","0.1010"
"79.50","6.63","33.29","0.1017"
"80.00","6.67","33.29","0.1023"
"80.50","6.71","33.29","0.1029"
"81.00","6.75","33.28","0.1036"
"81.50","6.79","33.28","0.1042"
"82.00","6.83","33.27","0.1049"
"82.50","6.88","33.27","0.1055"
"83.00","6.92","33.26","0.1061"
"83.50","6.96","33.25","0.1068"
"84.00","7.00","33.24","0.1074"
"84.50","7.04","33.23","0.1081"
"85.00","7.08","33.22","0.1087"
"85.50","7.13","33.20","0.1093"
"86.00","7.17","33.19","0.1100"
"86.50","7.21","33.18","0.1106"
"87.00","7.25","33.16","0.1113"
"87.50","7.29","33.15","0.1119"
"88.00","7.33","33.14","0.1125"
"88.50","7.38","33.12","0.1132"
"89.00","7.42","33.11","0.1138"
"89.50","7.46","33.09","0.1144"
"90.00","7.50","33.07","0.1151"
"90.50","7.54","33.05","0.1157"
"91.00","7.58","33.04","0.1164"
"91.50","7.63","33.02","0.1170"
"92.00","7.67","33.00","0.1176"
"92.50","7.71","32.98","0.1183"
"93.00","7.75","32.97","0.1189"
"93.50","7.79","32.95","0.1196"
"94.00","7.83","32.93","0.1202"
"94.50","7.88","32.91","0.1208"
"95.00","7.92","32.89","0.1215"
"95.50","7.96","32.87","0.1221"
"96.00","8.00","32.85","0.1228"
"96.50","8.04","32.82","0.1234"
"97.00","8.08","32.80","0.1240"
"97.50","8.13","32.77","0.1247"
"98.00","8.17","32.75","0.1253"
"98.50","8.21","32.72","0.1260"
"99.00","8.25","32.69","0.1266"
"99.50","8.29","32.66","0.1272"
"100.00","8.33","32.63","0.1279"
"100.50","8.38","32.60","0.1285"
"101.00","8.42","32.57","0.1292"
"101.50","8.46","32.53","0.1298"
"102.00","8.50","32.50","0.1304"
"102.50","8.54","32.47","0.1311"
"103.00","8.58","32.44","0.1317"
"103.50","8.63","32.40","0.1323"
"104.00","8.67","32.37","0.1330"
"104.50","8.71","32.34","0.1336"
"105.00","8.75","32.31","0.1343"
"105.50","8.79","32.27","0.1349"
"106.00","8.83","32.23","0.1355"
"106.50","8.88","32.20","0.1362"
"107.00","8.92","32.16","0.1368"
"107.50","8.96","32.13","0.1375"
"108.00","9.00","32.09","0.1381"
"108.50","9.04","32.05","0.1387"
"109.00","9.08","32.01","0.1394"
"109.50","9.13","31.94","0.1400"
"110.00","9.17","31.91","0.1407"
"110.50","9.21","31.86","0.1413"
"111.00","9.25","31.83","0.1419"
"111.50","9.29","31.79","0.1426"
"112.00","9.33","31.75","0.1432"
"112.50","9.38","31.71","0.1439"
"113.00","9.42","31.68","0.1445"
"113.50","9.46","31.63","0.1451"
"114.00","9.50","31.59","0.1458"
"114.50","9.54","31.55","0.1464"
"115.00","9.58","31.51","0.1471"
"115.50","9.63","31.47","0.1477"
"116.00","9.67","31.43","0.1483"
"116.50","9.71","31.39","0.1490"
"117.00","9.75","31.36","0.1496"
"117.50","9.79","31.31","0.1502"
"118.00","9.83","31.28","0.1509"
"118.50","9.88","31.24","0.1515"
"119.00","9.92","31.20","0.1522"
"119.50","9.96","31.16","0.1528"
"120.00","10.00","31.12","0.1534"
"120.50","10.04","31.09","0.1541"
"121.00","10.08","31.05","0.1547"
"121.50","10.13","31.01","0.1554"
"122.00","10.17","30.97","0.1560"
"122.50","10.21","30.93","0.1566"
"123.00","10.25","30.89","0.1573"
"123.50","10.29","30.84","0.1579"
"124.00","10.33","30.80","0.1586"
"124.50","10.38","30.76","0.1592"
"125.00","10.42","30.71","0.1598"
"125.50","10.46","30.67","0.1605"
"126.00","10.50","30.62","0.1611"
"126.50","10.54","30.58","0.1618"
"127.00","10.58","30.54","0.1624"
"127.50","10.63","30.50","0.1630"
"128.00","10.67","30.45","0.1637"
"128.50","10.71","30.40","0.1643"
"129.00","10.75","30.36","0.1650"
"129.50","10.79","30.32","0.1656"
"130.00","10.83","30.28","0.1662"
"130.50","10.88","30.23","0.1669"
"131.00","10.92","30.19","0.1675"
"131.50","10.96","30.15","0.1682"
"132.00","11.00","30.11","0.1688"
"132.50","11.04","30.07","0.1694"
"133.00","11.08","30.04","0.1701"
"133.50","11.13","30.00","0.1707"
"134.00","11.17","29.97","0.1713"
"134.50","11.21","29.93","0.1720"
"135.00","11.25","29.90","0.1726"
"135.50","11.29","29.86","0.1733"
"136.00","11.33","29.83","0.1739"
"136.50","11.38","29.80","0.1745"
"137.00","11.42","29.77","0.1752"
"137.50","11.46","29.73","0.1758"
"138.00","11.50","29.69","0.1765"
"138.50","11.54","29.66","0.1771"
"139.00","11.58","29.63","0.1777"
"139.50","11.63","29.59","0.1784"
"140.00","11.67","29.55","0.1790"
"140.50","11.71","29.52","0.1797"
"141.00","11.75","29.49","0.1803"
"141.50","11.79","29.45","0.1809"
"142.00","11.83","29.41","0.1816"
"142.50","11.88","29.38","0.1822"
"143.00","11.92","29.35","0.1829"
"143.50","11.96","29.31","0.1835"
"144.00","12.00","29.28","0.1841"
"144.50","12.04","29.24","0.1848"
"145.00","12.08","29.20","0.1854"
"145.50","12.13","29.17","0.1861"
"146.00","12.17","29.14","0.1867"
"146.50","12.21","29.11","0.1873"
"147.00","12.25","29.08","0.1880"
"147.50","12.29","29.05","0.1886"
"148.00","12.33","29.02","0.1893"
"148.50","12.38","28.98","0.1899"
"149.00","12.42","28.95","0.1905"
"149.50","12.46","28.92","0.1912"
"150.00","12.50","28.89","0.1918"
"150.50","12.54","28.85","0.1924"
"151.00","12.58","28.82","0.1931"
"151.50","12.63","28.79","0.1937"
"152.00","12.67","28.75","0.1944"
"152.50","12.71","28.72","0.1950"
"153.00","12.75","28.70","0.1956"
"153.50","12.79","28.66","0.1963"
"154.00","12.83","28.63","0.1969"
"154.50","12.88","28.61","0.1976"
"155.00","12.92","28.58","0.1982"
"155.50","12.96","28.55","0.1988"
"156.00","13.00","28.52","0.1995"
"156.50","13.04","28.50","0.2001"
"157.00","13.08","28.48","0.2008"
"157.50","13.13","28.45","0.2014"
"158.00","13.17","28.42","0.2020"
"158.50","13.21","28.40","0.2027"
"159.00","13.25","28.38","0.2033"
"159.50","13.29","28.35","0.2040"
"160.00","13.33","28.34","0.2046"
"160.50","13.38","28.31","0.2052"
"161.00","13.42","28.29","0.2059"
"161.50","13.46","28.27","0.2065"
"162.00","13.50","28.25","0.2072"
"162.50","13.54","28.23","0.2078"
"163.00","13.58","28.21","0.2084"
"163.50","13.63","28.19","0.2091"
"164.00","13.67","28.17","0.2097"
"164.50","13.71","28.15","0.2104"
"165.00","13.75","28.13","0.2110"
"165.50","13.79","28.11","0.2116"
"166.00","13.83","28.10","0.2123"
"166.50","13.88","28.08","0.2129"
"167.00","13.92","28.06","0.2135"
"167.50","13.96","28.04","0.2142"
"168.00","14.00","28.02","0.2148"
"168.50","14.04","28.00","0.2155"
"169.00","14.08","27.98","0.2161"
"169.50","14.13","27.94","0.2167"
"170.00","14.17","27.92","0.2174"
"170.50","14.21","27.91","0.2180"
"171.00","14.25","27.89","0.2187"
"171.50","14.29","27.88","0.2193"
"172.00","14.33","27.86","0.2199"
"172.50","14.38","27.84","0.2206"
"173.00","14.42","27.83","0.2212"
"173.50","14.46","27.82","0.2219"
"174.00","14.50","27.80","0.2225"
"174.50","14.54","27.79","0.2231"
"175.00","14.58","27.78","0.2238"
"175.50","14.63","27.76","0.2244"
"176.00","14.67","27.75","0.2251"
"176.50","14.71","27.74","0.2257"
"177.00","14.75","27.73","0.2263"
"177.50","14.79","27.71","0.2270"
"178.00","14.83","27.70","0.2276"
"178.50","14.88","27.69","0.2283"
"179.00","14.92","27.68","0.2289"
"179.50","14.96","27.67","0.2295"
"180.00","15.00","27.67","0.2302"
"180.50","15.04","27.66","0.2308"
"181.00","15.08","27.65","0.2314"
"181.50","15.13","27.65","0.2321"
"182.00","15.17","27.65","0.2327"
"182.50","15.21","27.64","0.2334"
"183.00","15.25","27.63","0.2340"
"183.50","15.29","27.63","0.2346"
"184.00","15.33","27.63","0.2353"
"184.50","15.38","27.63","0.2359"
"185.00","15.42","27.63","0.2366"
"185.50","15.46","27.62","0.2372"
"186.00","15.50","27.62","0.2378"
"186.50","15.54","27.61","0.2385"
"187.00","15.58","27.61","0.2391"
"187.50","15.63","27.60","0.2398"
"188.00","15.67","27.59","0.2404"
"188.50","15.71","27.59","0.2410"
"189.00","15.75","27.58","0.2417"
"189.50","15.79","27.58","0.2423"
"190.00","15.83","27.56","0.2430"
"190.50","15.88","27.56","0.2436"
"191.00","15.92","27.56","0.2442"
"191.50","15.96","27.51","0.2449"
"192.00","16.00","27.50","0.2455"
"192.50","16.04","27.49","0.2462"
"193.00","16.08","27.49","0.2468"
"193.50","16.13","27.49","0.2474"
"194.00","16.17","27.48","0.2481"
"194.50","16.21","27.48","0.2487"
"195.00","16.25","27.48","0.2494"
"195.50","16.29","27.47","0.2500"
"196.00","16.33","27.46","0.2506"
"196.50","16.38","27.46","0.2513"
"197.00","16.42","27.45","0.2519"
"197.50","16.46","27.45","0.2525"
"198.00","16.50","27.44","0.2532"
"198.50","16.54","27.44","0.2538"
"199.00","16.58","27.43","0.2545"
"199.50","16.63","27.42","0.2551"
"200.00","16.67","27.42","0.2557"
"200.50","16.71","27.41","0.2564"
"201.00","16.75","27.40","0.2570"
"201.50","16.79","27.39","0.2577"
"202.00","16.83","27.39","0.2583"
"202.50","16.88","27.38","0.2589"
"203.00","16.92","27.37","0.2596"
"203.50","16.96","27.36","0.2602"
"204.00","17.00","27.36","0.2609"
"204.50","17.04","27.35","0.2615"
"205.00","17.08","27.34","0.2621"
"205.50","17.13","27.33","0.2628"
"206.00","17.17","27.32","0.2634"
"206.50","17.21","27.31","0.2641"
"207.00","17.25","27.31","0.2647"
"207.50","17.29","27.31","0.2653"
"208.00","17.33","27.30","0.2660"
"208.50","17.38","27.29","0.2666"
"209.00","17.42","27.29","0.2673"
"209.50","17.46","27.29","0.2679"
"210.00","17.50","27.27","0.2685"
"210.50","17.54","27.26","0.2692"
"211.00","17.58","27.22","0.2698"
"211.50","17.63","27.21","0.2705"
"212.00","17.67","27.20","0.2711"
"212.50","17.71","27.19","0.2717"
"213.00","17.75","27.19","0.2724"
"213.50","17.79","27.18","0.2730"
"214.00","17.83","27.17","0.2736"
"214.50","17.88","27.16","0.2743"
"215.00","17.92","27.16","0.2749"
"215.50","17.96","27.14","0.2756"
"216.00","18.00","27.14","0.2762"
"216.50","18.04","27.13","0.2768"
"217.00","18.08","27.12","0.2775"
"217.50","18.13","27.11","0.2781"
"218.00","18.17","27.11","0.2788"
"218.50","18.21","27.11","0.2794"
"219.00","18.25","27.10","0.2800"
"219.50","18.29","27.09","0.2807"
"220.00","18.33","27.08","0.2813"
"220.50","18.38","27.08","0.2820"
"221.00","18.42","27.06","0.2826"
"221.50","18.46","27.06","0.2832"
"222.00","18.50","27.06","0.2839"
"222.50","18.54","27.05","0.2845"
"223.00","18.58","27.04","0.2852"
"223.50","18.63","27.03","0.2858"
"224.00","18.67","27.02","0.2864"
"224.50","18.71","27.01","0.2871"
"225.00","18.75","27.01","0.2877"
"225.50","18.79","27.01","0.2884"
"226.00","18.83","27.00","0.2890"
"226.50","18.88","26.99","0.2896"
"227.00","18.92","26.99","0.2903"
"227.50","18.96","26.99","0.2909"
"228.00","19.00","26.99","0.2915"
"228.50","19.04","26.98","0.2922"
"229.00","19.08","26.98","0.2928"
"229.50","19.13","26.98","0.2935"
"230.00","19.17","26.92","0.2941"
"230.50","19.21","26.92","0.2947"
"231.00","19.25","26.92","0.2954"
"231.50","19.29","26.92","0.2960"
"232.00","19.33","26.92","0.2967"
"232.50","19.38","26.92","0.2973"
"233.00","19.42","26.92","0.2979"
"233.50","19.46","26.92","0.2986"
"234.00","19.50","26.92","0.2992"
"234.50","19.54","26.92","0.2999"
"235.00","19.58","26.92","0.3005"
"235.50","19.63","26.92","0.3011"
"236.00","19.67","26.92","0.3018"
"236.50","19.71","26.92","0.3024"
"237.00","19.75","26.92","0.3031"
"237.50","19.79","26.92","0.3037"
"238.00","19.83","26.92","0.3043"
"238.50","19.88","26.92","0.3050"
"239.00","19.92","26.91","0.3056"
"239.50","19.96","26.90","0.3063"
"240.00","20.00","26.90","0.3069"
"240.50","20.04","26.90","0.3075"
"241.00","20.08","26.89","0.3082"
"241.50","20.13","26.89","0.3088"
"242.00","20.17","26.88","0.3094"
"242.50","20.21","26.88","0.3101"
"243.00","20.25","26.87","0.3107"
"243.50","20.29","26.86","0.3114"
"244.00","20.33","26.86","0.3120"
"244.50","20.38","26.85","0.3126"
"245.00","20.42","26.84","0.3133"
"245.50","20.46","26.84","0.3139"
"246.00","20.50","26.83","0.3146"
"246.50","20.54","26.81","0.3152"
"247.00","20.58","26.81","0.3158"
"247.50","20.63","26.75","0.3165"
"248.00","20.67","26.74","0.3171"
"248.50","20.71","26.72","0.3178"
"249.00","20.75","26.72","0.3184"
"249.50","20.79","26.71","0.3190"
"250.00","20.83","26.70","0.3197"
"250.50","20.88","26.69","0.3203"
"251.00","20.92","26.68","0.3210"
"251.50","20.96","26.67","0.3216"
"252.00","21.00","26.66","0.3222"
"252.50","21.04","26.66","0.3229"
"253.00","21.08","26.65","0.3235"
"253.50","21.13","26.64","0.3242"
"254.00","21.17","26.64","0.3248"
"254.50","21.21","26.63","0.3254"
"255.00","21.25","26.62","0.3261"
"255.50","21.29","26.61","0.3267"
"256.00","21.33","26.60","0.3274"
"256.50","21.38","26.60","0.3280"
"257.00","21.42","26.59","0.3286"
"257.50","21.46","26.57","0.3293"
"258.00","21.50","26.56","0.3299"
"258.50","21.54","26.55","0.3305"
"259.00","21.58","26.54","0.3312"
"259.50","21.63","26.52","0.3318"
"260.00","21.67","26.51","0.3325"
"260.50","21.71","26.50","0.3331"
"261.00","21.75","26.48","0.3337"
"261.50","21.79","26.47","0.3344"
"262.00","21.83","26.47","0.3350"
"262.50","21.88","26.45","0.3357"
"263.00","21.92","26.44","0.3363"
"263.50","21.96","26.44","0.3369"
"264.00","22.00","26.38","0.3376"
"264.50","22.04","26.36","0.3382"
"265.00","22.08","26.35","0.3389"
"265.50","22.13","26.35","0.3395"
"266.00","22.17","26.35","0.3401"
"266.50","22.21","26.34","0.3408"
"267.00","22.25","26.33","0.3414"
"267.50","22.29","26.34","0.3421"
"268.00","22.33","26.33","0.3427"
"268.50","22.38","26.32","0.3433"
"269.00","22.42","26.31","0.3440"
"269.50","22.46","26.31","0.3446"
"270.00","22.50","26.30","0.3453"
"270.50","22.54","26.30","0.3459"
"271.00","22.58","26.29","0.3465"
"271.50","22.63","26.28","0.3472"
"272.00","22.67","26.27","0.3478"
"272.50","22.71","26.27","0.3485"
"273.00","22.75","26.26","0.3491"
"273.50","22.79","26.25","0.3497"
"274.00","22.83","26.24","0.3504"
"274.50","22.88","26.23","0.3510"
"275.00","22.92","26.22","0.3516"
"275.50","22.96","26.21","0.3523"
"276.00","23.00","26.20","0.3529"
"276.50","23.04","26.19","0.3536"
"277.00","23.08","26.18","0.3542"
"277.50","23.13","26.16","0.3548"
"278.00","23.17","26.15","0.3555"
"278.50","23.21","26.14","0.3561"
"279.00","23.25","24.93","0.3568"
"279.50","23.29","24.92","0.3574"
"280.00","23.33","24.92","0.3580"
"280.50","23.38","24.92","0.3587"
"281.00","23.42","24.93","0.3593"
"281.50","23.46","24.95","0.3600"
"282.00","23.50","24.97","0.3606"
"282.50","23.54","24.98","0.3612"
"283.00","23.58","25.00","0.3619"
"283.50","23.63","25.02","0.3625"
"284.00","23.67","25.05","0.3632"
"284.50","23.71","25.06","0.3638"
"285.00","23.75","25.08","0.3644"
"285.50","23.79","25.11","0.3651"
"286.00","23.83","25.13","0.3657"
"286.50","23.88","25.15","0.3664"
"287.00","23.92","25.17","0.3670"
"287.50","23.96","25.18","0.3676"
"288.00","24.00","25.20","0.3683"
"288.50","24.04","25.20","0.3689"
"289.00","24.08","25.21","0.3695"
"289.50","24.13","25.22","0.3702"
"290.00","24.17","25.23","0.3708"
"290.50","24.21","25.24","0.3715"
"291.00","24.25","25.21","0.3721"
"291.50","24.29","25.21","0.3727"
"292.00","24.33","25.21","0.3734"
"292.50","24.38","25.23","0.3740"
"293.00","24.42","25.23","0.3747"
"293.50","24.46","25.24","0.3753"
"294.00","24.50","25.24","0.3759"
"294.50","24.54","25.25","0.3766"
"295.00","24.58","25.25","0.3772"
"295.50","24.63","25.25","0.3779"
"296.00","24.67","25.24","0.3785"
"296.50","24.71","25.24","0.3791"
"297.00","24.75","25.24","0.3798"
"297.50","24.79","25.23","0.3804"
"298.00","24.83","25.22","0.3811"
"298.50","24.88","25.19","0.3817"
"299.00","24.92","25.18","0.3823"
"299.50","24.96","25.17","0.3830"
"300.00","25.00","25.17","0.3836"
"300.50","25.04","25.15","0.3843"
"301.00","25.08","25.14","0.3849"
"301.50","25.13","25.10","0.3855"
"302.00","25.17","25.09","0.3862"
"302.50","25.21","25.07","0.3868"
"303.00","25.25","25.05","0.3875"
"303.50","25.29","25.04","0.3881"
"304.00","25.33","25.03","0.3887"
"304.50","25.38","25.02","0.3894"
"305.00","25.42","24.96","0.3900"
"305.50","25.46","24.95","0.3906"
"306.00","25.50","24.94","0.3913"
"306.50","25.54","24.93","0.3919"
"307.00","25.58","24.92","0.3926"
"307.50","25.63","24.91","0.3932"
"308.00","25.67","24.10","0.3938"
"308.50","25.71","24.13","0.3945"
"309.00","25.75","24.16","0.3951"
"309.50","25.79","24.17","0.3958"
"310.00","25.83","24.19","0.3964"
"310.50","25.88","24.20","0.3970"
"311.00","25.92","24.23","0.3977"
"311.50","25.96","24.24","0.3983"
"312.00","26.00","24.25","0.3990"
"312.50","26.04","24.26","0.3996"
"313.00","26.08","24.28","0.4002"
"313.50","26.13","24.29","0.4009"
"314.00","26.17","24.30","0.4015"
"314.50","26.21","24.31","0.4022"
"315.00","26.25","24.32","0.4028"
"315.50","26.29","24.32","0.4034"
"316.00","26.33","24.32","0.4041"
"316.50","26.38","24.32","0.4047"
"317.00","26.42","24.32","0.4054"
"317.50","26.46","24.32","0.4060"
"318.00","26.50","24.33","0.4066"
"318.50","26.54","24.33","0.4073"
"319.00","26.58","24.32","0.4079"
"319.50","26.63","24.32","0.4085"
"320.00","26.67","24.32","0.4092"
"320.50","26.71","24.31","0.4098"
"321.00","26.75","24.30","0.4105"
"321.50","26.79","24.30","0.4111"
"322.00","26.83","24.30","0.4117"
"322.50","26.88","24.29","0.4124"
"323.00","26.92","24.28","0.4130"
"323.50","26.96","24.28","0.4137"
"324.00","27.00","24.27","0.4143"
"324.50","27.04","24.26","0.4149"
"325.00","27.08","24.25","0.4156"
"325.50","27.13","24.24","0.4162"
"326.00","27.17","24.23","0.4169"
"326.50","27.21","24.22","0.4175"
"327.00","27.25","24.18","0.4181"
"327.50","27.29","24.17","0.4188"
"328.00","27.33","24.13","0.4194"
"328.50","27.38","24.10","0.4201"
"329.00","27.42","24.10","0.4207"
"329.50","27.46","24.09","0.4213"
"330.00","27.50","24.08","0.4220"
"330.50","27.54","24.08","0.4226"
"331.00","27.58","24.07","0.4233"
"331.50","27.63","24.06","0.4239"
"332.00","27.67","24.05","0.4245"
"332.50","27.71","24.05","0.4252"
"333.00","27.75","24.04","0.4258"
"333.50","27.79","24.03","0.4265"
"334.00","27.83","24.02","0.4271"
"334.50","27.88","24.01","0.4277"
"335.00","27.92","24.00","0.4284"
"335.50","27.96","23.99","0.4290"
"336.00","28.00","23.98","0.4297"
"336.50","28.04","23.97","0.4303"
"337.00","28.08","23.96","0.4309"
"337.50","28.13","23.95","0.4316"
"338.00","28.17","23.94","0.4322"
"338.50","28.21","23.94","0.4328"
"339.00","28.25","23.92","0.4335"
"339.50","28.29","23.92","0.4341"
"340.00","28.33","23.91","0.4348"
"340.50","28.38","23.91","0.4354"
"341.00","28.42","23.90","0.4360"
"341.50","28.46","23.89","0.4367"
"342.00","28.50","23.89","0.4373"
"342.50","28.54","23.88","0.4380"
"343.00","28.58","23.89","0.4386"
"343.50","28.63","23.72","0.4392"
"344.00","28.67","23.71","0.4399"
"344.50","28.71","23.70","0.4405"
"345.00","28.75","23.71","0.4412"
"345.50","28.79","23.71","0.4418"
"346.00","28.83","23.70","0.4424"
"346.50","28.88","23.71","0.4431"
"347.00","28.92","23.71","0.4437"
"347.50","28.96","23.72","0.4444"
"348.00","29.00","23.73","0.4450"
"348.50","29.04","23.73","0.4456"
"349.00","29.08","23.75","0.4463"
"349.50","29.13","23.76","0.4469"
"350.00","29.17","23.77","0.4475"
"350.50","29.21","23.79","0.4482"
"351.00","29.25","23.80","0.4488"
"351.50","29.29","23.82","0.4495"
"352.00","29.33","23.84","0.4501"
"352.50","29.38","23.86","0.4507"
"353.00","29.42","23.89","0.4514"
"353.50","29.46","23.90","0.4520"
"354.00","29.50","23.93","0.4527"
"354.50","29.54","23.96","0.4533"
"355.00","29.58","23.98","0.4539"
"355.50","29.63","24.00","0.4546"
"356.00","29.67","24.03","0.4552"
"356.50","29.71","24.06","0.4559"
"357.00","29.75","24.08","0.4565"
"357.50","29.79","24.10","0.4571"
"358.00","29.83","24.13","0.4578"
"358.50","29.88","24.15","0.4584"
"359.00","29.92","24.18","0.4591"
"359.50","29.96","24.21","0.4597"
"360.00","30.00","24.24","0.4603"
"360.50","30.04","24.27","0.4610"
"361.00","30.08","24.30","0.4616"
"361.50","30.13","24.33","0.4623"
"362.00","30.17","24.36","0.4629"
"362.50","30.21","24.38","0.4635"
"363.00","30.25","24.41","0.4642"
"363.50","30.29","24.45","0.4648"
"364.00","30.33","24.48","0.4655"
"364.50","30.38","24.50","0.4661"
"365.00","30.42","24.53","0.4667"
"365.50","30.46","24.57","0.4674"
"366.00","30.50","24.60","0.4680"
"366.50","30.54","24.62","0.4686"
"367.00","30.58","24.66","0.4693"
"367.50","30.63","24.69","0.4699"
"368.00","30.67","24.72","0.4706"
"368.50","30.71","24.76","0.4712"
"369.00","30.75","24.79","0.4718"
"369.50","30.79","24.83","0.4725"
"370.00","30.83","24.86","0.4731"
"370.50","30.88","24.90","0.4738"
"371.00","30.92","24.94","0.4744"
"371.50","30.96","24.97","0.4750"
"372.00","31.00","25.01","0.4757"
"372.50","31.04","25.05","0.4763"
"373.00","31.08","25.08","0.4770"
"373.50","31.13","25.11","0.4776"
"374.00","31.17","25.15","0.4782"
"374.50","31.21","25.19","0.4789"
"375.00","31.25","25.22","0.4795"
"375.50","31.29","25.26","0.4802"
"375.54","31.30","14.57","0.4802"