File: Lab5/data/N02D4340T300C_1.csv
System ID,,"4483C1713"
Method name only,,"Tension_Round_Heat_Treat_NEW"
Test type,,"Tension"
Sample file name,,"N02D4340T300C"
Last test date,,"Monday, October 14, 2024"
Last test time,,"6:09:49 PM"
Course,,"NPRE 432"
Lab Section Number,,"02"
Group,,"D"
Material,,"4340"
Heat Treatment,,"T300C"
Other Information,,""
Crosshead Speed,(mm/min),"4.00"
Geometry,,"Circular"
Gage Diameter,(mm),"7.29"
Grip Diameter,(mm),"12.62"
Rockwell Hardness,,"33.9"
Rockwell Scale,,"HRC"
Extensometer Gage Length,(mm),"25.40"
Final Gage Diameter,(mm),"5.38"
Fracture Notes and Location,,"Slightly ductile failure, cup/cone structure"
Notes During Test,,""

Results Table 1
,,"1"
Maximum Force,(kN),"64.85"
Maximum Strain,(%),"27.87"

Time,Displacement,Force,Strain 1
(s),(mm),(kN),(mm/mm)
"0.00","0.00","0.1044","-0.00002429"
"0.50","0.03","0.6531","0.0001617"
"1.00","0.07","1.512","0.0005769"
"1.50","0.10","2.239","0.0009724"
"2.00","0.13","2.917","0.001087"
"2.50","0.17","3.563","0.001173"
"3.00","0.20","4.145","0.001256"
"3.50","0.23","4.616","0.001317"
"4.00","0.27","4.946","0.001355"
"4.50","0.30","5.206","0.001387"
"5.00","0.33","5.327","0.001410"
"5.50","0.37","5.138","0.001403"
"6.00","0.40","4.593","0.001326"
"6.50","0.43","3.816","0.001223"
"7.00","0.47","2.943","0.001104"
"7.50","0.50","2.196","0.0009949"
"8.00","0.53","1.604","0.0008944"
"8.50","0.57","1.076","0.0008190"
"9.00","0.60","0.6645","0.0007418"
"9.50","0.63","0.3984","0.0006984"
"10.00","0.67","0.5931","0.0007203"
"10.50","0.70","0.9311","0.0007926"
"11.00","0.73","1.275","0.0008576"
"11.50","0.77","1.629","0.0009137"
"12.00","0.80","2.008","0.0009698"
"12.50","0.83","2.413","0.001019"
"13.00","0.87","2.840","0.001083"
"13.50","0.90","3.285","0.001133"
"14.00","0.93","3.740","0.001187"
"14.50","0.97","4.202","0.001251"
"15.00","1.00","4.665","0.001305"
"15.50","1.03","5.117","0.001370"
"16.00","1.07","5.489","0.001419"
"16.50","1.10","5.773","0.001461"
"17.00","1.13","6.029","0.001485"
"17.50","1.17","6.251","0.001508"
"18.00","1.20","6.432","0.001530"
"18.50","1.23","6.562","0.001541"
"19.00","1.27","6.654","0.001550"
"19.50","1.30","6.661","0.001556"
"20.00","1.33","6.567","0.001536"
"20.50","1.37","6.275","0.001505"
"21.00","1.40","5.769","0.001448"
"21.50","1.43","5.168","0.001372"
"22.00","1.47","4.519","0.001280"
"22.50","1.50","3.533","0.001145"
"23.00","1.53","1.923","0.0009453"
"23.50","1.57","0.5340","0.0007717"
"24.00","1.60","0.3293","0.0007533"
"24.50","1.63","0.2174","0.0007563"
"25.00","1.67","0.1525","0.0007378"
"25.50","1.70","0.3236","0.0007752"
"26.00","1.73","0.5501","0.0008056"
"26.50","1.77","0.7846","0.0008369"
"27.00","1.80","1.001","0.0008622"
"27.50","1.83","1.230","0.0008875"
"28.00","1.87","1.473","0.0009183"
"28.50","1.90","1.729","0.0009587"
"29.00","1.93","2.000","0.0009948"
"29.50","1.97","2.291","0.001028"
"30.00","2.00","2.593","0.001075"
"30.50","2.03","2.916","0.001111"
"31.00","2.07","3.256","0.001165"
"31.50","2.10","3.608","0.001188"
"32.00","2.13","3.970","0.001246"
"32.50","2.17","4.345","0.001289"
"33.00","2.20","4.725","0.001334"
"33.50","2.23","5.108","0.001387"
"34.00","2.27","5.495","0.001439"
"34.50","2.30","5.884","0.001481"
"35.00","2.33","6.282","0.001539"
"35.50","2.37","6.675","0.001582"
"36.00","2.40","7.055","0.001636"
"36.50","2.43","7.423","0.001666"
"37.00","2.47","7.785","0.001725"
"37.50","2.50","8.150","0.001774"
"38.00","2.53","8.510","0.001815"
"38.50","2.57","8.866","0.001862"
"39.00","2.60","9.224","0.001913"
"39.50","2.63","9.583","0.001957"
"40.00","2.67","9.945","0.002010"
"40.50","2.70","10.31","0.002052"
"41.00","2.73","10.67","0.002104"
"41.50","2.77","11.04","0.002147"
"42.00","2.80","11.42","0.002191"
"42.50","2.83","11.79","0.002239"
"43.00","2.87","12.16","0.002282"
"43.50","2.90","12.54","0.002335"
"44.00","2.93","12.92","0.002387"
"44.50","2.97","13.30","0.002429"
"45.00","3.00","13.69","0.002482"
"45.50","3.03","14.07","0.002526"
"46.00","3.07","14.46","0.002575"
"46.50","3.10","14.85","0.002623"
"47.00","3.13","15.25","0.002676"
"47.50","3.17","15.65","0.002720"
"48.00","3.20","16.05","0.002780"
"48.50","3.23","16.45","0.002821"
"49.00","3.27","16.86","0.002879"
"49.50","3.30","17.27","0.002930"
"50.00","3.33","17.68","0.002978"
"50.50","3.37","18.09","0.003029"
"51.00","3.40","18.51","0.003080"
"51.50","3.43","18.92","0.003145"
"52.00","3.47","19.34","0.003194"
"52.50","3.50","19.76","0.003250"
"53.00","3.53","20.18","0.003299"
"53.50","3.57","20.62","0.003358"
"54.00","3.60","21.04","0.003405"
"54.50","3.63","21.47","0.003459"
"55.00","3.67","21.90","0.003517"
"55.50","3.70","22.33","0.003564"
"56.00","3.73","22.77","0.003631"
"56.50","3.77","23.21","0.003683"
"57.00","3.80","23.65","0.003736"
"57.50","3.83","24.09","0.003794"
"58.00","3.87","24.54","0.003856"
"58.50","3.90","24.98","0.003906"
"59.00","3.93","25.43","0.003965"
"59.50","3.97","25.88","0.004027"
"60.00","4.00","26.33","0.004079"
"60.50","4.03","26.79","0.004138"
"61.00","4.07","27.24","0.004192"
"61.50","4.10","27.69","0.004255"
"62.00","4.13","28.15","0.004313"
"62.50","4.17","28.60","0.004370"
"63.00","4.20","29.05","0.004434"
"63.50","4.23","29.51","0.004486"
"64.00","4.27","29.97","0.004551"
"64.50","4.30","30.44","0.004614"
"65.00","4.33","30.90","0.004664"
"65.50","4.37","31.37","0.004726"
"66.00","4.40","31.83","0.004786"
"66.50","4.43","32.30","0.004845"
"67.00","4.47","32.77","0.004912"
"67.50","4.50","33.24","0.004980"
"68.00","4.53","33.71","0.005031"
"68.50","4.57","34.18","0.005101"
"69.00","4.60","34.66","0.005154"
"69.50","4.63","35.13","0.005225"
"70.00","4.67","35.60","0.005287"
"70.50","4.70","36.08","0.005350"
"71.00","4.73","36.56","0.005411"
"71.50","4.77","37.04","0.005476"
"72.00","4.80","37.52","0.005548"
"72.50","4.83","38.00","0.005610"
"73.00","4.87","38.47","0.005665"
"73.50","4.90","38.95","0.005731"
"74.00","4.93","39.43","0.005804"
"74.50","4.97","39.91","0.005874"
"75.00","5.00","40.39","0.005941"
"75.50","5.03","40.87","0.006003"
"76.00","5.07","41.35","0.006072"
"76.50","5.10","41.84","0.006150"
"77.00","5.13","42.32","0.006213"
"77.50","5.17","42.80","0.006293"
"78.00","5.20","43.29","0.006356"
"78.50","5.23","43.77","0.006434"
"79.00","5.27","44.26","0.006506"
"79.50","5.30","44.74","0.006587"
"80.00","5.33","45.22","0.006658"
"80.50","5.37","45.71","0.006727"
"81.00","5.40","46.20","0.006810"
"81.50","5.43","46.68","0.006889"
"82.00","5.47","47.16","0.006973"
"82.50","5.50","47.64","0.007046"
"83.00","5.53","48.12","0.007134"
"83.50","5.57","48.61","0.007222"
"84.00","5.60","49.08","0.007314"
"84.50","5.63","49.55","0.007417"
"85.00","5.67","50.03","0.007530"
"85.50","5.70","50.48","0.007660"
"86.00","5.73","50.93","0.007794"
"86.50","5.77","51.37","0.007965"
"87.00","5.80","51.78","0.008164"
"87.50","5.83","52.18","0.008383"
"88.00","5.87","52.58","0.008611"
"88.50","5.90","52.97","0.008846"
"89.00","5.93","53.36","0.009093"
"89.50","5.97","53.75","0.009318"
"90.00","6.00","54.14","0.009556"
"90.50","6.03","54.53","0.009781"
"91.00","6.07","54.92","0.01002"
"91.50","6.10","55.30","0.01026"
"92.00","6.13","55.68","0.01052"
"92.50","6.17","56.06","0.01076"
"93.00","6.20","56.43","0.01102"
"93.50","6.23","56.80","0.01129"
"94.00","6.27","57.16","0.01155"
"94.50","6.30","57.53","0.01183"
"95.00","6.33","57.88","0.01213"
"95.50","6.37","58.22","0.01243"
"96.00","6.40","58.56","0.01274"
"96.50","6.43","58.90","0.01306"
"97.00","6.47","59.22","0.01339"
"97.50","6.50","59.54","0.01373"
"98.00","6.53","59.85","0.01408"
"98.50","6.57","60.15","0.01446"
"99.00","6.60","60.44","0.01484"
"99.50","6.63","60.73","0.01525"
"100.00","6.67","61.00","0.01566"
"100.50","6.70","61.27","0.01608"
"101.00","6.73","61.53","0.01653"
"101.50","6.77","61.78","0.01700"
"102.00","6.80","62.02","0.01748"
"102.50","6.83","62.24","0.01797"
"103.00","6.87","62.46","0.01849"
"103.50","6.90","62.67","0.01902"
"104.00","6.93","62.87","0.01956"
"104.50","6.97","63.06","0.02015"
"105.00","7.00","63.23","0.02073"
"105.50","7.03","63.40","0.02134"
"106.00","7.07","63.57","0.02196"
"106.50","7.10","63.72","0.02262"
"107.00","7.13","63.86","0.02330"
"107.50","7.17","63.99","0.02398"
"108.00","7.20","64.11","0.02470"
"108.50","7.23","64.23","0.02544"
"109.00","7.27","64.33","0.02621"
"109.50","7.30","64.43","0.02700"
"110.00","7.33","64.52","0.02780"
"110.50","7.37","64.60","0.02864"
"111.00","7.40","64.66","0.02952"
"111.50","7.43","64.72","0.03040"
"112.00","7.47","64.77","0.03133"
"112.50","7.50","64.81","0.03229"
"113.00","7.53","64.84","0.03329"
"113.50","7.57","64.85","0.03432"
"114.00","7.60","64.85","0.03540"
"114.50","7.63","64.83","0.03652"
"115.00","7.67","64.79","0.03769"
"115.50","7.70","64.72","0.03891"
"116.00","7.73","64.62","0.04019"
"116.50","7.77","64.49","0.04153"
"117.00","7.80","64.33","0.04291"
"117.50","7.83","64.14","0.04434"
"118.00","7.87","63.93","0.04581"
"118.50","7.90","63.68","0.04728"
"119.00","7.93","63.43","0.04881"
"119.50","7.97","63.16","0.05033"
"120.00","8.00","62.88","0.05187"
"120.50","8.03","62.58","0.05342"
"121.00","8.07","62.28","0.05497"
"121.50","8.10","61.98","0.05655"
"122.00","8.13","61.66","0.05813"
"122.50","8.17","61.34","0.05971"
"123.00","8.20","61.02","0.06129"
"123.50","8.23","60.71","0.06287"
"124.00","8.27","60.37","0.06446"
"124.50","8.30","60.04","0.06607"
"125.00","8.33","59.71","0.06767"
"125.50","8.37","59.38","0.06926"
"126.00","8.40","59.05","0.07086"
"126.50","8.43","58.72","0.07246"
"127.00","8.47","58.38","0.07406"
"127.50","8.50","58.04","0.07567"
"128.00","8.53","57.71","0.07727"
"128.50","8.57","57.36","0.07889"
"129.00","8.60","57.03","0.08050"
"129.50","8.63","56.68","0.08211"
"130.00","8.67","56.34","0.08372"
"130.50","8.70","55.98","0.08533"
"131.00","8.73","55.63","0.08697"
"131.50","8.77","55.27","0.08859"
"132.00","8.80","54.92","0.09021"
"132.50","8.83","54.56","0.09182"
"133.00","8.87","54.20","0.09347"
"133.50","8.90","53.83","0.09512"
"134.00","8.93","53.45","0.09675"
"134.50","8.97","53.07","0.09841"
"135.00","9.00","52.69","0.1001"
"135.50","9.03","52.30","0.1017"
"136.00","9.07","51.91","0.1034"
"136.50","9.10","51.51","0.1050"
"137.00","9.13","51.11","0.1067"
"137.50","9.17","50.70","0.1084"
"138.00","9.20","50.28","0.1101"
"138.50","9.23","49.86","0.1118"
"139.00","9.27","49.43","0.1135"
"139.50","9.30","48.99","0.1152"
"140.00","9.33","48.55","0.1169"
"140.50","9.37","48.09","0.1187"
"141.00","9.40","47.63","0.1204"
"141.50","9.43","47.17","0.1221"
"142.00","9.47","46.67","0.1239"
"142.50","9.50","46.16","0.1257"
"143.00","9.53","-0.01787","0.2446"
"143.50","9.57","-0.01375","0.2736"
"144.00","9.60","-0.01087","0.2738"
"144.50","9.63","-0.007952","0.2760"
"145.00","9.67","-0.006018","0.2769"
"145.50","9.70","-0.003985","0.2781"
"145.81","9.72","-0.003834","0.2787"