File: Lab5/data/N02D4340NM_1.csv
System ID,,"4483C1713"
Method name only,,"Tension_Round_Heat_Treat_NEW"
Test type,,"Tension"
Sample file name,,"N02D4340NM"
Last test date,,"Monday, October 14, 2024"
Last test time,,"5:48:42 PM"
Course,,"NPRE 432"
Lab Section Number,,"02"
Group,,"D"
Material,,"4340"
Heat Treatment,,"NM"
Other Information,,""
Crosshead Speed,(mm/min),"4.00"
Geometry,,"Circular"
Gage Diameter,(mm),"7.20"
Grip Diameter,(mm),"12.72"
Rockwell Hardness,,"23.5"
Rockwell Scale,,"HRC"
Extensometer Gage Length,(mm),"25.40"
Final Gage Diameter,(mm),"6.25"
Fracture Notes and Location,,"Brittle fracture, flat surface"
Notes During Test,,""

Results Table 1
,,"1"
Maximum Force,(kN),"58.73"
Maximum Strain,(%),"24.95"

Time,Displacement,Force,Strain 1
(s),(mm),(kN),(mm/mm)
"0.00","0.00","0.4122","-0.0001370"
"0.50","0.03","0.6492","-0.0001018"
"1.00","0.07","0.6804","-0.0001075"
"1.50","0.10","0.6859","-0.0001201"
"2.00","0.13","0.6894","-0.0001097"
"2.50","0.17","0.6803","-0.0001124"
"3.00","0.20","0.6647","-0.0001114"
"3.50","0.23","0.6410","-0.0001168"
"4.00","0.27","0.6009","-0.0001244"
"4.50","0.30","0.5544","-0.0001444"
"5.00","0.33","0.4988","-0.0001441"
"5.50","0.37","0.4253","-0.0001602"
"6.00","0.40","0.3515","-0.0001603"
"6.50","0.43","0.2749","-0.0001661"
"7.00","0.47","0.2060","-0.0001877"
"7.50","0.50","0.1481","-0.0001959"
"8.00","0.53","0.1017","-0.0002071"
"8.50","0.57","0.06348","-0.0002091"
"9.00","0.60","0.03866","-0.0002027"
"9.50","0.63","0.02536","-0.0001870"
"10.00","0.67","0.02048","-0.0001614"
"10.50","0.70","0.07224","-0.0001478"
"11.00","0.73","0.1008","-0.0001586"
"11.50","0.77","0.1423","-0.0001749"
"12.00","0.80","0.1989","-0.0001898"
"12.50","0.83","0.2748","-0.0001892"
"13.00","0.87","0.3639","-0.0001892"
"13.50","0.90","0.4715","-0.0001906"
"14.00","0.93","0.6005","-0.0001799"
"14.50","0.97","0.7268","-0.0001652"
"15.00","1.00","0.8338","-0.0001492"
"15.50","1.03","0.9288","-0.0001416"
"16.00","1.07","1.031","-0.0001336"
"16.50","1.10","1.134","-0.0001275"
"17.00","1.13","1.235","-0.0001131"
"17.50","1.17","1.341","-0.0001093"
"18.00","1.20","1.442","-0.00009634"
"18.50","1.23","1.542","-0.00009060"
"19.00","1.27","1.642","-0.00007412"
"19.50","1.30","1.748","-0.00006274"
"20.00","1.33","1.857","-0.00004680"
"20.50","1.37","1.972","-0.00001828"
"21.00","1.40","2.095","-0.000004329"
"21.50","1.43","2.224","0.00001605"
"22.00","1.47","2.358","0.00003011"
"22.50","1.50","2.496","0.00005358"
"23.00","1.53","2.648","0.00007081"
"23.50","1.57","2.811","0.0001044"
"24.00","1.60","2.979","0.0001298"
"24.50","1.63","3.152","0.0001396"
"25.00","1.67","3.329","0.0001689"
"25.50","1.70","3.514","0.0001901"
"26.00","1.73","3.706","0.0002065"
"26.50","1.77","3.906","0.0002338"
"27.00","1.80","4.112","0.0002608"
"27.50","1.83","4.324","0.0002903"
"28.00","1.87","4.543","0.0003148"
"28.50","1.90","4.774","0.0003415"
"29.00","1.93","5.004","0.0003711"
"29.50","1.97","5.241","0.0003937"
"30.00","2.00","5.482","0.0004181"
"30.50","2.03","5.731","0.0004535"
"31.00","2.07","5.989","0.0004778"
"31.50","2.10","6.253","0.0005159"
"32.00","2.13","6.521","0.0005444"
"32.50","2.17","6.793","0.0005753"
"33.00","2.20","7.069","0.0006105"
"33.50","2.23","7.348","0.0006416"
"34.00","2.27","7.628","0.0006812"
"34.50","2.30","7.910","0.0007208"
"35.00","2.33","8.194","0.0007483"
"35.50","2.37","8.486","0.0007875"
"36.00","2.40","8.772","0.0008227"
"36.50","2.43","9.066","0.0008579"
"37.00","2.47","9.363","0.0008959"
"37.50","2.50","9.660","0.0009236"
"38.00","2.53","9.961","0.0009667"
"38.50","2.57","10.26","0.0009976"
"39.00","2.60","10.56","0.001042"
"39.50","2.63","10.86","0.001081"
"40.00","2.67","11.17","0.001125"
"40.50","2.70","11.47","0.001163"
"41.00","2.73","11.78","0.001191"
"41.50","2.77","12.09","0.001232"
"42.00","2.80","12.40","0.001282"
"42.50","2.83","12.71","0.001320"
"43.00","2.87","13.02","0.001360"
"43.50","2.90","13.33","0.001403"
"44.00","2.93","13.64","0.001442"
"44.50","2.97","13.95","0.001485"
"45.00","3.00","14.26","0.001517"
"45.50","3.03","14.58","0.001564"
"46.00","3.07","14.89","0.001608"
"46.50","3.10","15.20","0.001658"
"47.00","3.13","15.51","0.001696"
"47.50","3.17","15.82","0.001740"
"48.00","3.20","16.13","0.001796"
"48.50","3.23","16.43","0.001828"
"49.00","3.27","16.73","0.001880"
"49.50","3.30","17.03","0.001924"
"50.00","3.33","17.32","0.001965"
"50.50","3.37","17.61","0.002014"
"51.00","3.40","17.90","0.002057"
"51.50","3.43","18.18","0.002094"
"52.00","3.47","18.45","0.002136"
"52.50","3.50","18.72","0.002179"
"53.00","3.53","18.97","0.002219"
"53.50","3.57","19.22","0.002260"
"54.00","3.60","19.45","0.002296"
"54.50","3.63","19.66","0.002326"
"55.00","3.67","19.85","0.002356"
"55.50","3.70","20.01","0.002380"
"56.00","3.73","20.12","0.002404"
"56.50","3.77","20.18","0.002420"
"57.00","3.80","20.11","0.002407"
"57.50","3.83","19.79","0.002374"
"58.00","3.87","18.83","0.002279"
"58.50","3.90","3.448","-0.005358"
"59.00","3.93","4.339","-0.004788"
"59.50","3.97","5.030","-0.004936"
"60.00","4.00","5.641","-0.004826"
"60.50","4.03","6.218","-0.004739"
"61.00","4.07","6.764","-0.004672"
"61.50","4.10","7.260","-0.004632"
"62.00","4.13","7.721","-0.004589"
"62.50","4.17","8.177","-0.004555"
"63.00","4.20","8.627","-0.004516"
"63.50","4.23","9.074","-0.004459"
"64.00","4.27","9.525","-0.004416"
"64.50","4.30","9.976","-0.004360"
"65.00","4.33","10.43","-0.004313"
"65.50","4.37","10.88","-0.004259"
"66.00","4.40","11.33","-0.004218"
"66.50","4.43","11.79","-0.004172"
"67.00","4.47","12.25","-0.004131"
"67.50","4.50","12.71","-0.004081"
"68.00","4.53","13.17","-0.004041"
"68.50","4.57","13.63","-0.003988"
"69.00","4.60","14.10","-0.003938"
"69.50","4.63","14.57","-0.003877"
"70.00","4.67","15.04","-0.003841"
"70.50","4.70","15.51","-0.003794"
"71.00","4.73","15.98","-0.003743"
"71.50","4.77","16.46","-0.003693"
"72.00","4.80","16.94","-0.003649"
"72.50","4.83","17.41","-0.003591"
"73.00","4.87","17.88","-0.003535"
"73.50","4.90","18.35","-0.003491"
"74.00","4.93","18.82","-0.003437"
"74.50","4.97","19.27","-0.003387"
"75.00","5.00","19.72","-0.003335"
"75.50","5.03","20.16","-0.003280"
"76.00","5.07","20.59","-0.003225"
"76.50","5.10","21.01","-0.003181"
"77.00","5.13","21.42","-0.003114"
"77.50","5.17","21.82","-0.003059"
"78.00","5.20","22.23","-0.002993"
"78.50","5.23","22.63","-0.002922"
"79.00","5.27","23.02","-0.002852"
"79.50","5.30","23.39","-0.002778"
"80.00","5.33","23.79","-0.002716"
"80.50","5.37","24.18","-0.002637"
"81.00","5.40","24.57","-0.002561"
"81.50","5.43","24.95","-0.002479"
"82.00","5.47","25.34","-0.002408"
"82.50","5.50","25.72","-0.002331"
"83.00","5.53","26.11","-0.002253"
"83.50","5.57","26.49","-0.002172"
"84.00","5.60","26.88","-0.002085"
"84.50","5.63","27.26","-0.002005"
"85.00","5.67","27.65","-0.001915"
"85.50","5.70","28.04","-0.001824"
"86.00","5.73","28.42","-0.001735"
"86.50","5.77","28.81","-0.001648"
"87.00","5.80","29.20","-0.001561"
"87.50","5.83","29.58","-0.001464"
"88.00","5.87","29.97","-0.001373"
"88.50","5.90","30.35","-0.001268"
"89.00","5.93","30.74","-0.001173"
"89.50","5.97","31.13","-0.001082"
"90.00","6.00","31.51","-0.0009748"
"90.50","6.03","31.89","-0.0008697"
"91.00","6.07","32.28","-0.0007629"
"91.50","6.10","32.66","-0.0006584"
"92.00","6.13","33.05","-0.0005434"
"92.50","6.17","33.43","-0.0004333"
"93.00","6.20","33.81","-0.0003138"
"93.50","6.23","34.19","-0.0002090"
"94.00","6.27","34.57","-0.00008463"
"94.50","6.30","34.95","0.00003507"
"95.00","6.33","35.32","0.0001595"
"95.50","6.37","35.70","0.0002847"
"96.00","6.40","36.08","0.0005044"
"96.50","6.43","36.45","0.0007420"
"97.00","6.47","36.82","0.0007282"
"97.50","6.50","37.20","0.0008598"
"98.00","6.53","37.57","0.0009954"
"98.50","6.57","37.94","0.001140"
"99.00","6.60","38.31","0.001280"
"99.50","6.63","38.68","0.001433"
"100.00","6.67","39.05","0.001577"
"100.50","6.70","39.41","0.001727"
"101.00","6.73","39.77","0.001870"
"101.50","6.77","40.13","0.002022"
"102.00","6.80","40.49","0.002173"
"102.50","6.83","40.84","0.002334"
"103.00","6.87","41.20","0.002497"
"103.50","6.90","41.56","0.002666"
"104.00","6.93","41.91","0.002833"
"104.50","6.97","42.25","0.003006"
"105.00","7.00","42.60","0.003179"
"105.50","7.03","42.95","0.003364"
"106.00","7.07","43.29","0.003546"
"106.50","7.10","43.63","0.003740"
"107.00","7.13","43.97","0.003916"
"107.50","7.17","44.30","0.004108"
"108.00","7.20","44.64","0.004322"
"108.50","7.23","44.97","0.004524"
"109.00","7.27","45.29","0.004722"
"109.50","7.30","45.62","0.004933"
"110.00","7.33","45.94","0.005153"
"110.50","7.37","46.26","0.005379"
"111.00","7.40","46.58","0.005598"
"111.50","7.43","46.89","0.005832"
"112.00","7.47","47.21","0.006062"
"112.50","7.50","47.51","0.006312"
"113.00","7.53","47.82","0.006556"
"113.50","7.57","48.12","0.006802"
"114.00","7.60","48.41","0.007057"
"114.50","7.63","48.71","0.007322"
"115.00","7.67","49.00","0.007593"
"115.50","7.70","49.29","0.007861"
"116.00","7.73","49.57","0.008147"
"116.50","7.77","49.85","0.008425"
"117.00","7.80","50.12","0.008708"
"117.50","7.83","50.40","0.008999"
"118.00","7.87","50.67","0.009305"
"118.50","7.90","50.93","0.009612"
"119.00","7.93","51.19","0.009928"
"119.50","7.97","51.44","0.01025"
"120.00","8.00","51.69","0.01057"
"120.50","8.03","51.94","0.01091"
"121.00","8.07","52.19","0.01124"
"121.50","8.10","52.43","0.01158"
"122.00","8.13","52.66","0.01195"
"122.50","8.17","52.89","0.01232"
"123.00","8.20","53.11","0.01268"
"123.50","8.23","53.33","0.01305"
"124.00","8.27","53.55","0.01343"
"124.50","8.30","53.76","0.01382"
"125.00","8.33","53.96","0.01422"
"125.50","8.37","54.16","0.01462"
"126.00","8.40","54.36","0.01501"
"126.50","8.43","54.55","0.01544"
"127.00","8.47","54.73","0.01586"
"127.50","8.50","54.92","0.01629"
"128.00","8.53","55.09","0.01673"
"128.50","8.57","55.26","0.01718"
"129.00","8.60","55.44","0.01763"
"129.50","8.63","55.60","0.01810"
"130.00","8.67","55.75","0.01858"
"130.50","8.70","55.91","0.01905"
"131.00","8.73","56.05","0.01953"
"131.50","8.77","56.20","0.02003"
"132.00","8.80","56.34","0.02053"
"132.50","8.83","56.48","0.02103"
"133.00","8.87","56.61","0.02155"
"133.50","8.90","56.73","0.02209"
"134.00","8.93","56.85","0.02262"
"134.50","8.97","56.97","0.02316"
"135.00","9.00","57.09","0.02372"
"135.50","9.03","57.20","0.02428"
"136.00","9.07","57.30","0.02485"
"136.50","9.10","57.41","0.02543"
"137.00","9.13","57.50","0.02602"
"137.50","9.17","57.60","0.02661"
"138.00","9.20","57.69","0.02722"
"138.50","9.23","57.77","0.02784"
"139.00","9.27","57.85","0.02846"
"139.50","9.30","57.93","0.02909"
"140.00","9.33","58.00","0.02974"
"140.50","9.37","58.08","0.03040"
"141.00","9.40","58.14","0.03107"
"141.50","9.43","58.21","0.03175"
"142.00","9.47","58.27","0.03245"
"142.50","9.50","58.32","0.03314"
"143.00","9.53","58.37","0.03386"
"143.50","9.57","58.43","0.03459"
"144.00","9.60","58.47","0.03533"
"144.50","9.63","58.52","0.03609"
"145.00","9.67","58.56","0.03686"
"145.50","9.70","58.59","0.03765"
"146.00","9.73","58.62","0.03845"
"146.50","9.77","58.65","0.03928"
"147.00","9.80","58.67","0.04013"
"147.50","9.83","58.70","0.04100"
"148.00","9.87","58.71","0.04189"
"148.50","9.90","58.72","0.04280"
"149.00","9.93","58.73","0.04374"
"149.50","9.97","58.73","0.04471"
"150.00","10.00","58.72","0.04571"
"150.50","10.03","58.71","0.04674"
"151.00","10.07","58.69","0.04782"
"151.50","10.10","58.66","0.04894"
"152.00","10.13","58.62","0.05007"
"152.50","10.17","58.57","0.05126"
"153.00","10.20","58.50","0.05248"
"153.50","10.23","58.43","0.05375"
"154.00","10.27","58.33","0.05505"
"154.50","10.30","58.23","0.05637"
"155.00","10.33","58.13","0.05772"
"155.50","10.37","58.01","0.05909"
"156.00","10.40","57.87","0.06048"
"156.50","10.43","57.74","0.06189"
"157.00","10.47","57.60","0.06329"
"157.50","10.50","57.45","0.06472"
"158.00","10.53","57.29","0.06617"
"158.50","10.57","57.13","0.06762"
"159.00","10.60","56.96","0.06906"
"159.50","10.63","56.79","0.07050"
"160.00","10.67","56.62","0.07198"
"160.50","10.70","56.43","0.07344"
"161.00","10.73","56.25","0.07492"
"161.50","10.77","56.06","0.07639"
"162.00","10.80","55.87","0.07786"
"162.50","10.83","55.66","0.07935"
"163.00","10.87","55.46","0.08084"
"163.50","10.90","55.26","0.08234"
"164.00","10.93","55.05","0.08383"
"164.50","10.97","54.83","0.08533"
"165.00","11.00","54.60","0.08685"
"165.50","11.03","54.37","0.08837"
"166.00","11.07","54.13","0.08990"
"166.50","11.10","53.89","0.09143"
"167.00","11.13","53.62","0.09299"
"167.50","11.17","53.34","0.09456"
"168.00","11.20","-0.05214","0.2493"
"168.50","11.23","-0.04890","0.2493"
"169.00","11.27","-0.04480","0.2494"
"169.50","11.30","-0.04213","0.2494"
"170.00","11.33","-0.03927","0.2494"
"170.50","11.37","-0.03685","0.2494"
"171.00","11.40","-0.03534","0.2494"
"171.50","11.43","-0.03333","0.2495"
"172.00","11.47","-0.03214","0.2495"
"172.50","11.50","-0.03068","0.2495"
"173.00","11.53","-0.02940","0.2495"
"173.50","11.57","-0.02906","0.2495"
"174.00","11.60","-0.02779","0.2495"
"174.50","11.63","-0.02721","0.2495"
"175.00","11.67","-0.02688","0.2495"
"175.50","11.70","-0.02566","0.2495"
"176.00","11.73","-0.02502","0.2495"
"176.02","11.73","-0.02517","0.2495"